File: instron-2.2.csv
Time,Extension,Load,Tensile stress,Tensile strain,Strain 1,Displacement (Strain 1)
(sec),(mm),(N),(MPa),(mm/mm),(mm/mm),(mm)
0.00000,0.06894,306.78303,14.47800,0.00002,0.00002,0.00081
0.55000,0.07874,458.69970,21.64740,0.00005,0.00005,0.00226
1.10000,0.08801,569.78068,26.88964,0.00007,0.00007,0.00341
1.65000,0.09722,679.88550,32.08581,0.00009,0.00009,0.00460
2.20000,0.10625,794.61969,37.50046,0.00011,0.00011,0.00552
2.75000,0.11551,914.69316,43.16708,0.00014,0.00014,0.00683
3.30000,0.12466,1037.37749,48.95692,0.00016,0.00016,0.00799
3.85000,0.13393,1161.65457,54.82192,0.00018,0.00018,0.00910
4.40000,0.14314,1286.48747,60.71315,0.00020,0.00020,0.01023
4.95000,0.15222,1407.56331,66.42709,0.00023,0.00023,0.01154
5.50000,0.16137,1526.09497,72.02094,0.00025,0.00025,0.01259
6.05000,0.17052,1640.66609,77.42789,0.00028,0.00028,0.01386
6.60000,0.17961,1748.62985,82.52303,0.00029,0.00029,0.01475
7.15000,0.18888,1856.74690,87.62539,0.00032,0.00032,0.01586
7.70000,0.19802,1948.82527,91.97084,0.00034,0.00034,0.01678
8.25000,0.20723,2052.28571,96.85344,0.00036,0.00036,0.01787
8.80000,0.21650,2158.85881,101.88294,0.00038,0.00038,0.01885
9.35000,0.22559,2260.32343,106.67136,0.00040,0.00040,0.01980
9.90000,0.23473,2361.55652,111.44884,0.00041,0.00041,0.02056
10.45000,0.24394,2459.98632,116.09404,0.00043,0.00043,0.02159
11.00000,0.25303,2143.69800,101.16746,0.00044,0.00044,0.02209
11.55000,0.26218,2290.86559,108.11273,0.00047,0.00047,0.02370
12.10000,0.27132,2436.60845,114.99077,0.00050,0.00050,0.02516
12.65000,0.28053,2568.63013,121.22127,0.00053,0.00053,0.02627
13.20000,0.28974,2689.50984,126.92593,0.00055,0.00055,0.02748
13.75000,0.29901,2781.17042,131.25168,0.00057,0.00057,0.02856
14.30000,0.30810,2833.98926,133.74435,0.00057,0.00057,0.02868
14.85000,0.31718,2911.22403,137.38928,0.00059,0.00059,0.02965
15.40000,0.32627,2990.71167,141.14055,0.00060,0.00060,0.03013
15.95000,0.33548,3069.37154,144.85274,0.00062,0.00062,0.03079
16.50000,0.34463,3147.88297,148.55792,0.00064,0.00064,0.03188
17.05000,0.35395,3225.27327,152.21021,0.00065,0.00065,0.03250
17.60000,0.36304,3300.31998,155.75188,0.00066,0.00066,0.03325
18.15000,0.37231,3378.49781,159.44131,0.00068,0.00068,0.03384
18.70000,0.38140,3448.48260,162.74411,0.00070,0.00070,0.03476
19.25000,0.39049,3520.62322,166.14864,0.00071,0.00071,0.03536
19.80000,0.39969,3591.54865,169.49582,0.00072,0.00072,0.03608
20.35000,0.40878,3660.99849,172.77336,0.00073,0.00073,0.03668
20.90000,0.41793,3731.37482,176.09464,0.00074,0.00074,0.03723
21.45000,0.42726,3800.43313,179.35370,0.00076,0.00076,0.03807
22.00000,0.43634,3867.79681,182.53279,0.00077,0.00077,0.03869
22.55000,0.44561,3935.12473,185.71019,0.00079,0.00079,0.03950
23.10000,0.45482,3998.75380,188.71304,0.00080,0.00080,0.03995
23.65000,0.46391,4062.60192,191.72623,0.00082,0.00082,0.04094
24.20000,0.47305,4119.88273,194.42947,0.00082,0.00082,0.04092
24.75000,0.48208,4180.08938,197.27080,0.00084,0.00084,0.04179
25.30000,0.49123,4240.93045,200.14207,0.00085,0.00085,0.04241
25.85000,0.50062,4300.51051,202.95383,0.00086,0.00086,0.04298
26.40000,0.50971,4363.32189,205.91809,0.00087,0.00087,0.04370
26.95000,0.51897,4434.40825,209.27286,0.00088,0.00088,0.04414
27.50000,0.52812,4503.89422,212.55211,0.00090,0.00090,0.04499
28.05000,0.53721,4574.40242,215.87961,0.00091,0.00091,0.04546
28.60000,0.54636,4643.44658,219.13800,0.00093,0.00093,0.04647
29.15000,0.55544,4712.18675,222.38205,0.00094,0.00094,0.04693
29.70000,0.56465,4781.62989,225.65929,0.00096,0.00096,0.04801
30.25000,0.57392,4852.50875,229.00426,0.00097,0.00097,0.04868
30.80000,0.58301,4921.92470,232.28021,0.00098,0.00098,0.04911
31.35000,0.59233,4989.62924,235.47539,0.00100,0.00100,0.04994
31.90000,0.60142,5055.20776,238.57024,0.00101,0.00101,0.05049
32.45000,0.61051,5119.76443,241.61685,0.00102,0.00102,0.05114
33.00000,0.61984,5175.55475,244.24976,0.00104,0.00104,0.05178
33.55000,0.62881,5237.47951,247.17218,0.00105,0.00105,0.05255
34.10000,0.63795,5294.57740,249.86679,0.00106,0.00106,0.05312
34.65000,0.64722,5350.82817,252.52144,0.00107,0.00107,0.05363
35.20000,0.65631,5407.35573,255.18913,0.00108,0.00108,0.05407
35.75000,0.66564,5466.12553,257.96265,0.00110,0.00110,0.05478
36.30000,0.67478,5520.16422,260.51291,0.00110,0.00110,0.05511
36.85000,0.68393,5575.30895,263.11536,0.00112,0.00112,0.05603
37.40000,0.69302,5627.66418,265.58615,0.00114,0.00114,0.05679
37.95000,0.70217,5681.44172,268.12405,0.00114,0.00114,0.05708
38.50000,0.71126,5733.14093,270.56390,0.00115,0.00115,0.05758
39.05000,0.72052,5786.32616,273.07388,0.00115,0.00115,0.05772
39.60000,0.72973,5837.60962,275.49408,0.00116,0.00116,0.05818
40.15000,0.73894,5888.39576,277.89084,0.00117,0.00117,0.05862
40.70000,0.74809,5935.98038,280.13651,0.00119,0.00119,0.05955
41.25000,0.75729,5982.05552,282.31091,0.00120,0.00120,0.06002
41.80000,0.76638,6026.54256,284.41040,0.00121,0.00121,0.06068
42.35000,0.77547,6072.63222,286.58551,0.00122,0.00122,0.06083
42.90000,0.78468,6116.24569,288.64377,0.00123,0.00123,0.06168
43.45000,0.79383,6161.15816,290.76331,0.00124,0.00124,0.06207
44.00000,0.80303,6204.59616,292.81326,0.00126,0.00126,0.06284
44.55000,0.81236,6250.42319,294.97598,0.00127,0.00127,0.06338
45.10000,0.82145,6296.10717,297.13196,0.00128,0.00128,0.06387
45.65000,0.83054,6339.39952,299.17505,0.00129,0.00129,0.06433
46.20000,0.83974,6381.09595,301.14282,0.00130,0.00130,0.06499
46.75000,0.84883,6422.50255,303.09692,0.00131,0.00131,0.06527
47.30000,0.85792,6460.10041,304.87128,0.00132,0.00132,0.06602
47.85000,0.86719,6501.79461,306.83896,0.00134,0.00134,0.06683
48.40000,0.87639,6540.84459,308.68182,0.00134,0.00134,0.06714
48.95000,0.88560,6584.18611,310.72723,0.00135,0.00135,0.06761
49.50000,0.89481,6628.42765,312.81512,0.00136,0.00136,0.06820
50.05000,0.90396,6670.37740,314.79486,0.00138,0.00138,0.06900
50.60000,0.91299,6712.52757,316.78406,0.00139,0.00139,0.06937
51.15000,0.92225,6760.83490,319.06384,0.00140,0.00140,0.06998
51.70000,0.93128,6803.92832,321.09753,0.00141,0.00141,0.07067
52.25000,0.94043,6853.74290,323.44843,0.00143,0.00143,0.07127
52.80000,0.94976,6901.28654,325.69217,0.00143,0.00143,0.07170
53.35000,0.95890,6945.01176,327.75568,0.00145,0.00145,0.07251
53.90000,0.96811,6991.54362,329.95166,0.00146,0.00146,0.07324
54.45000,0.97738,7033.01281,331.90872,0.00148,0.00148,0.07395
55.00000,0.98635,7071.23727,333.71265,0.00149,0.00149,0.07451
55.55000,0.99555,7112.47623,335.65881,0.00150,0.00150,0.07504
56.10000,1.00470,7146.80031,337.27869,0.00151,0.00151,0.07552
56.65000,1.01373,7183.23439,338.99811,0.00152,0.00152,0.07624
57.20000,1.02300,7218.84668,340.67877,0.00153,0.00153,0.07666
57.75000,1.03227,7253.54701,342.31638,0.00155,0.00155,0.07755
58.30000,1.04147,7286.59928,343.87622,0.00156,0.00156,0.07792
58.85000,1.05068,7313.28949,345.13580,0.00157,0.00157,0.07858
59.40000,1.05971,7345.39703,346.65106,0.00158,0.00158,0.07916
59.95000,1.06886,7373.70476,347.98697,0.00159,0.00159,0.07944
60.50000,1.07800,7400.62669,349.25751,0.00160,0.00160,0.07995
61.05000,1.08709,7425.47885,350.43036,0.00161,0.00161,0.08061
61.60000,1.09636,7442.87521,351.25134,0.00163,0.00163,0.08125
62.15000,1.10551,7460.57108,352.08646,0.00163,0.00163,0.08163
62.70000,1.11472,7486.47675,353.30902,0.00164,0.00164,0.08219
63.25000,1.12398,7511.08229,354.47021,0.00165,0.00165,0.08259
63.80000,1.13307,7536.09613,355.65070,0.00166,0.00166,0.08307
64.35001,1.14228,7560.06017,356.78165,0.00165,0.00165,0.08274
64.90000,1.15137,7579.97036,357.72125,0.00166,0.00166,0.08299
65.45000,1.16045,7598.54391,358.59781,0.00167,0.00167,0.08346
66.00000,1.16972,7617.42070,359.48865,0.00167,0.00167,0.08359
66.55000,1.17887,7636.50537,360.38931,0.00168,0.00168,0.08385
67.10001,1.18808,7656.30975,361.32394,0.00169,0.00169,0.08430
67.65000,1.19728,7678.83658,362.38705,0.00169,0.00169,0.08457
68.20001,1.20637,7699.12675,363.34460,0.00170,0.00170,0.08497
68.75000,1.21558,7717.20558,364.19778,0.00170,0.00170,0.08505
69.30000,1.22473,7734.75394,365.02594,0.00171,0.00171,0.08544
69.85001,1.23376,7749.62455,365.72775,0.00172,0.00172,0.08582
70.40000,1.24296,7765.17838,366.46176,0.00172,0.00172,0.08607
70.95001,1.25223,7782.51514,367.27994,0.00172,0.00172,0.08609
71.50000,1.26144,7802.85522,368.23987,0.00173,0.00173,0.08640
72.05000,1.27071,7823.41063,369.20993,0.00174,0.00174,0.08683
72.60001,1.27973,7839.99488,369.99258,0.00175,0.00175,0.08726
73.15000,1.28882,7854.30893,370.66812,0.00175,0.00175,0.08732
73.70001,1.29803,7867.20812,371.27686,0.00175,0.00175,0.08769
74.25000,1.30712,7878.88169,371.82776,0.00176,0.00176,0.08788
74.80000,1.31633,7896.89943,372.67807,0.00176,0.00176,0.08819
75.35001,1.32553,7917.88176,373.66830,0.00177,0.00177,0.08828
75.90000,1.33474,7936.93438,374.56744,0.00178,0.00178,0.08896
76.45001,1.34395,7962.47870,375.77295,0.00178,0.00178,0.08915
77.00000,1.35310,7980.97774,376.64600,0.00179,0.00179,0.08945
77.55000,1.36224,8000.18236,377.55231,0.00179,0.00179,0.08972
78.10001,1.37139,8022.49238,378.60519,0.00181,0.00181,0.09035
78.65000,1.38054,8038.40458,379.35614,0.00182,0.00182,0.09088
79.20001,1.38957,8056.71588,380.22028,0.00182,0.00182,0.09123
79.75000,1.39884,8074.89604,381.07828,0.00184,0.00184,0.09189
80.30000,1.40810,8092.73124,381.91995,0.00185,0.00185,0.09257
80.85001,1.41725,8110.91438,382.77808,0.00186,0.00186,0.09292
81.40000,1.42646,8130.07653,383.68240,0.00187,0.00187,0.09374
81.95001,1.43561,8147.34399,384.49731,0.00189,0.00189,0.09450
82.50001,1.44469,8163.04162,385.23813,0.00191,0.00191,0.09537
83.05000,1.45384,8175.60032,385.83081,0.00192,0.00192,0.09623
83.60001,1.46293,8193.81028,386.69019,0.00194,0.00194,0.09700
84.15000,1.47214,8211.24688,387.51306,0.00197,0.00197,0.09826
84.70001,1.48134,8225.24205,388.17355,0.00199,0.00199,0.09942
85.25001,1.49055,8239.45329,388.84421,0.00201,0.00201,0.10049
85.80000,1.49982,8252.46796,389.45840,0.00204,0.00204,0.10179
86.35001,1.50891,8263.44788,389.97659,0.00207,0.00207,0.10342
86.90000,1.51806,8276.12802,390.57501,0.00211,0.00211,0.10539
87.45001,1.52720,8285.29820,391.00778,0.00215,0.00215,0.10775
88.00001,1.53623,8293.95577,391.41635,0.00221,0.00221,0.11042
88.55000,1.54550,8305.37900,391.95544,0.00226,0.00226,0.11307
89.10001,1.55471,8313.16486,392.32288,0.00233,0.00233,0.11637
89.65000,1.56385,8319.97469,392.64426,0.00240,0.00240,0.11994
90.20001,1.57312,8324.43237,392.85461,0.00247,0.00247,0.12339
90.75001,1.58221,8332.96999,393.25754,0.00254,0.00254,0.12702
91.30000,1.59136,8342.54473,393.70941,0.00260,0.00260,0.12990
91.85001,1.60056,8348.08573,393.97089,0.00266,0.00266,0.13320
92.40000,1.60959,8351.00338,394.10858,0.00273,0.00273,0.13655
92.95001,1.61874,8356.61292,394.37332,0.00280,0.00280,0.13989
93.50001,1.62807,8363.28715,394.68829,0.00287,0.00287,0.14345
94.05000,1.63722,8368.47574,394.93317,0.00294,0.00294,0.14696
94.60001,1.64648,8369.86750,394.99884,0.00301,0.00301,0.15062
95.15000,1.65563,8371.73313,395.08688,0.00308,0.00308,0.15416
95.70001,1.66466,8369.08221,394.96179,0.00316,0.00316,0.15780
96.25001,1.67381,8373.98618,395.19321,0.00323,0.00323,0.16167
96.80000,1.68289,8371.43287,395.07272,0.00332,0.00332,0.16580
97.35001,1.69216,8366.36797,394.83368,0.00341,0.00341,0.17057
97.90000,1.70137,8365.94850,394.81390,0.00350,0.00350,0.17512
98.45001,1.71058,8370.05675,395.00778,0.00361,0.00361,0.18042
99.00001,1.71978,8372.80378,395.13742,0.00372,0.00372,0.18576
99.55000,1.72887,8377.90444,395.37814,0.00381,0.00381,0.19039
100.10001,1.73808,8384.02882,395.66714,0.00391,0.00391,0.19531
100.65000,1.74723,8380.15601,395.48438,0.00402,0.00402,0.20078
101.20001,1.75626,8372.79260,395.13690,0.00412,0.00412,0.20588
101.75001,1.76546,8376.17069,395.29630,0.00421,0.00421,0.21053
102.30000,1.77467,8378.27623,395.39569,0.00431,0.00431,0.21538
102.85001,1.78388,8384.72024,395.69980,0.00441,0.00441,0.22058
103.40000,1.79315,8378.50124,395.40628,0.00450,0.00450,0.22480
103.95001,1.80223,8376.43445,395.30875,0.00460,0.00460,0.22979
104.50001,1.81138,8370.46355,395.02698,0.00469,0.00469,0.23454
105.05000,1.82047,8371.83073,395.09149,0.00479,0.00479,0.23929
105.60001,1.82962,8372.22189,395.10995,0.00487,0.00487,0.24363
106.15000,1.83877,8370.32795,395.02057,0.00497,0.00497,0.24841
106.70001,1.84803,8378.49379,395.40594,0.00507,0.00507,0.25348
107.25001,1.85724,8371.86947,395.09332,0.00517,0.00517,0.25858
107.80000,1.86645,8372.11832,395.10507,0.00527,0.00527,0.26358
108.35001,1.87560,8378.09816,395.38727,0.00537,0.00537,0.26833
108.90000,1.88468,8372.58622,395.12714,0.00547,0.00547,0.27367
109.45001,1.89389,8368.40421,394.92978,0.00558,0.00558,0.27924
110.00001,1.90310,8367.96537,394.90909,0.00569,0.00569,0.28462
110.55000,1.91213,8362.10325,394.63242,0.00579,0.00579,0.28939
111.10001,1.92128,8365.04176,394.77112,0.00588,0.00588,0.29415
111.65000,1.93054,8365.36735,394.78647,0.00598,0.00598,0.29909
112.20001,1.93969,8364.42932,394.74219,0.00608,0.00608,0.30422
112.75001,1.94896,8359.14016,394.49258,0.00619,0.00619,0.30944
113.30000,1.95811,8350.78806,394.09842,0.00630,0.00630,0.31493
113.85001,1.96719,8351.12408,394.11429,0.00640,0.00640,0.32007
114.40001,1.97634,8347.11865,393.92526,0.00651,0.00651,0.32540
114.95001,1.98543,8343.51033,393.75497,0.00661,0.00661,0.33062
115.50001,1.99464,8348.31074,393.98151,0.00671,0.00671,0.33542
116.05000,2.00390,8351.52790,394.13333,0.00682,0.00682,0.34082
116.60001,2.01305,8365.83003,394.80829,0.00692,0.00692,0.34593
117.15001,2.02226,8370.76679,395.04129,0.00703,0.00703,0.35175
117.70001,2.03147,8371.85681,395.09271,0.00716,0.00716,0.35812
118.25001,2.04050,8370.93294,395.04913,0.00728,0.00728,0.36421
118.80000,2.04964,8365.73392,394.80377,0.00743,0.00743,0.37143
119.35001,2.05873,8365.31371,394.78394,0.00757,0.00757,0.37852
119.90001,2.06794,8360.84485,394.57303,0.00774,0.00774,0.38680
120.45001,2.07727,8362.19192,394.63660,0.00791,0.00791,0.39532
121.00001,2.08641,8367.81338,394.90192,0.00805,0.00805,0.40255
121.55000,2.09562,8372.32992,395.11505,0.00822,0.00822,0.41111
122.10001,2.10477,8367.70609,394.89685,0.00838,0.00838,0.41909
122.65001,2.11386,8365.25410,394.78113,0.00855,0.00855,0.42742
123.20001,2.12312,8364.23710,394.73312,0.00872,0.00872,0.43602
123.75001,2.13209,8361.91103,394.62335,0.00888,0.00888,0.44424
124.30000,2.14130,8369.54489,394.98361,0.00905,0.00905,0.45226
124.85001,2.15051,8368.57632,394.93790,0.00920,0.00920,0.46015
125.40001,2.15972,8365.58416,394.79669,0.00937,0.00937,0.46861
125.95001,2.16898,8362.91015,394.67050,0.00955,0.00955,0.47736
126.50001,2.17813,8361.65398,394.61124,0.00971,0.00971,0.48553
127.05000,2.18722,8354.64075,394.28024,0.00990,0.00990,0.49476
127.60001,2.19643,8359.05746,394.48868,0.01007,0.01007,0.50355
128.15001,2.20545,8356.75597,394.38007,0.01022,0.01022,0.51116
128.70002,2.21454,8350.38796,394.07956,0.01037,0.01037,0.51864
129.25000,2.22387,8352.53671,394.18094,0.01056,0.01056,0.52783
129.80000,2.23308,8350.58987,394.08908,0.01075,0.01075,0.53733
130.35001,2.24229,8344.08104,393.78189,0.01091,0.01091,0.54545
130.90001,2.25143,8344.69572,393.81091,0.01109,0.01109,0.55427
131.45002,2.26052,8342.56038,393.71014,0.01127,0.01127,0.56374
132.00000,2.26973,8340.91157,393.63232,0.01144,0.01144,0.57199
132.55000,2.27888,8341.84811,393.67651,0.01161,0.01161,0.58049
133.10000,2.28796,8339.05637,393.54477,0.01178,0.01178,0.58911
133.65002,2.29717,8339.41773,393.56183,0.01196,0.01196,0.59796
134.20002,2.30644,8344.03485,393.77972,0.01212,0.01212,0.60614
134.75000,2.31559,8346.04055,393.87439,0.01230,0.01230,0.61505
135.30000,2.32479,8348.61472,393.99585,0.01246,0.01246,0.62312
135.85000,2.33394,8349.73902,394.04892,0.01264,0.01264,0.63222
136.40002,2.34303,8352.65070,394.18634,0.01281,0.01281,0.64070
136.95002,2.35218,8352.14555,394.16251,0.01297,0.01297,0.64832
137.50000,2.36133,8347.44424,393.94061,0.01315,0.01315,0.65769
138.05000,2.37047,8348.31521,393.98172,0.01331,0.01331,0.66556
138.60000,2.37968,8349.69580,394.04688,0.01348,0.01348,0.67415
139.15002,2.38895,8353.52242,394.22748,0.01367,0.01367,0.68363
139.70002,2.39816,8353.25867,394.21503,0.01385,0.01385,0.69245
140.25000,2.40724,8351.69405,394.14117,0.01401,0.01401,0.70063
140.80000,2.41639,8352.89434,394.19781,0.01419,0.01419,0.70944
141.35000,2.42554,8354.26748,394.26263,0.01435,0.01435,0.71736
141.90002,2.43469,8347.41741,393.93936,0.01453,0.01453,0.72648
142.45002,2.44378,8346.76102,393.90839,0.01469,0.01469,0.73471
143.00000,2.45310,8347.61411,393.94864,0.01487,0.01487,0.74357
143.55000,2.46225,8343.69138,393.76352,0.01505,0.01505,0.75271
144.10000,2.47146,8352.76917,394.19193,0.01521,0.01521,0.76050
144.65002,2.48067,8358.36232,394.45587,0.01538,0.01538,0.76881
145.20002,2.48975,8364.47775,394.74448,0.01553,0.01553,0.77673
145.75000,2.49890,8370.85918,395.04565,0.01571,0.01571,0.78538
146.30000,2.50805,8365.12223,394.77490,0.01587,0.01587,0.79370
146.85000,2.51708,8357.27081,394.40436,0.01605,0.01605,0.80236
147.40002,2.52640,8359.92396,394.52957,0.01622,0.01622,0.81103
147.95002,2.53555,8348.07679,393.97049,0.01639,0.01639,0.81963
148.50000,2.54476,8347.25425,393.93167,0.01657,0.01657,0.82853
149.05000,2.55397,8348.74436,394.00198,0.01674,0.01674,0.83711
149.60000,2.56312,8347.32801,393.93515,0.01692,0.01692,0.84596
150.15002,2.57220,8343.89478,393.77310,0.01709,0.01709,0.85449
150.70002,2.58135,8344.54298,393.80371,0.01727,0.01727,0.86348
151.25000,2.59038,8346.96740,393.91812,0.01744,0.01744,0.87222
151.80000,2.59971,8351.90192,394.15100,0.01760,0.01760,0.88004
152.35000,2.60891,8352.23570,394.16675,0.01777,0.01777,0.88873
152.90002,2.61812,8358.72218,394.47287,0.01796,0.01796,0.89801
153.45002,2.62733,8363.17763,394.68314,0.01811,0.01811,0.90568
154.00000,2.63636,8359.54770,394.51181,0.01828,0.01828,0.91379
154.55000,2.64557,8348.30776,393.98138,0.01847,0.01847,0.92353
155.10000,2.65477,8346.00776,393.87283,0.01864,0.01864,0.93180
155.65002,2.66374,8343.94917,393.77570,0.01882,0.01882,0.94100
156.20002,2.67301,8345.05782,393.82800,0.01898,0.01898,0.94916
156.75000,2.68222,8202.65785,387.10773,0.01928,0.01928,0.96414
157.30000,2.69142,8253.59896,389.51178,0.01943,0.01943,0.97143
157.85000,2.70063,8347.86743,393.96060,0.01953,0.01953,0.97632
158.40002,2.70984,8412.51761,397.01163,0.01964,0.01964,0.98187
158.95002,2.71893,8448.64920,398.71680,0.01975,0.01975,0.98760
159.50000,2.72807,8473.16831,399.87390,0.01986,0.01986,0.99306
160.05000,2.73710,8487.17913,400.53513,0.01997,0.01997,0.99845
160.60000,2.74631,8501.36206,401.20447,0.02008,0.02008,1.00388
161.15002,2.75552,8516.27588,401.90829,0.02018,0.02018,1.00909
161.70002,2.76479,8528.72133,402.49564,0.02028,0.02028,1.01415
162.25002,2.77399,8537.88480,402.92807,0.02038,0.02038,1.01920
162.80000,2.78314,8547.40515,403.37738,0.02048,0.02048,1.02422
163.35000,2.79217,8553.52283,403.66608,0.02059,0.02059,1.02939
163.90002,2.80132,8562.75558,404.10181,0.02068,0.02068,1.03401
164.45002,2.81046,8568.23847,404.36057,0.02078,0.02078,1.03891
165.00002,2.81967,8575.29044,404.69336,0.02087,0.02087,1.04364
165.55000,2.82882,8584.67072,405.13605,0.02097,0.02097,1.04872
166.10000,2.83809,8590.81745,405.42612,0.02107,0.02107,1.05348
166.65002,2.84730,8600.27671,405.87253,0.02117,0.02117,1.05860
167.20002,2.85644,8605.56737,406.12222,0.02128,0.02128,1.06406
167.75002,2.86559,8609.19729,406.29352,0.02137,0.02137,1.06845
168.30000,2.87474,8616.39753,406.63333,0.02147,0.02147,1.07341
168.85000,2.88383,8618.60737,406.73761,0.02158,0.02158,1.07883
169.40002,2.89297,8625.72938,407.07373,0.02167,0.02167,1.08346
169.95002,2.90218,8631.87686,407.36383,0.02177,0.02177,1.08857
170.50002,2.91145,8636.30250,407.57269,0.02187,0.02187,1.09359
171.05000,2.92060,8644.89600,407.97824,0.02197,0.02197,1.09835
171.60000,2.92986,8651.32436,408.28162,0.02206,0.02206,1.10316
172.15002,2.93895,8652.55892,408.33987,0.02217,0.02217,1.10829
172.70002,2.94804,8659.65411,408.67474,0.02227,0.02227,1.11357
173.25002,2.95719,8662.72897,408.81985,0.02237,0.02237,1.11850
173.80000,2.96628,8665.31432,408.94186,0.02246,0.02246,1.12298
174.35000,2.97548,8674.04342,409.35382,0.02256,0.02256,1.12814
174.90002,2.98481,8678.45416,409.56195,0.02267,0.02267,1.13329
175.45002,2.99390,8684.17919,409.83215,0.02276,0.02276,1.13810
176.00002,3.00317,8690.83405,410.14621,0.02286,0.02286,1.14300
176.55000,3.01219,8691.97994,410.20029,0.02296,0.02296,1.14784
177.10000,3.02134,8699.28896,410.54523,0.02305,0.02305,1.15240
177.65002,3.03055,8701.58225,410.65344,0.02314,0.02314,1.15704
178.20002,3.03964,8706.57414,410.88904,0.02325,0.02325,1.16268
178.75002,3.04879,8712.36399,411.16226,0.02335,0.02335,1.16752
179.30000,3.05811,8716.70842,411.36731,0.02345,0.02345,1.17227
179.85000,3.06720,8724.91151,411.75443,0.02355,0.02355,1.17728
180.40002,3.07653,8730.98448,412.04102,0.02365,0.02365,1.18234
180.95002,3.08562,8734.15098,412.19046,0.02374,0.02374,1.18718
181.50002,3.09476,8741.12695,412.51968,0.02384,0.02384,1.19199
182.05000,3.10391,8743.42322,412.62805,0.02394,0.02394,1.19683
182.60000,3.11294,8747.23569,412.80795,0.02403,0.02403,1.20149
183.15002,3.12215,8752.14711,413.03976,0.02413,0.02413,1.20661
183.70002,3.13141,8757.77155,413.30518,0.02422,0.02422,1.21123
184.25002,3.14056,8765.10069,413.65106,0.02432,0.02432,1.21616
184.80000,3.14983,8770.52248,413.90695,0.02442,0.02442,1.22115
185.35000,3.15892,8774.30364,414.08539,0.02452,0.02452,1.22577
185.90002,3.16807,8779.79398,414.34448,0.02462,0.02462,1.23079
186.45002,3.17727,8782.28545,414.46207,0.02471,0.02471,1.23552
187.00002,3.18630,8785.53018,414.61520,0.02481,0.02481,1.24039
187.55000,3.19545,8791.06671,414.87650,0.02491,0.02491,1.24547
188.10000,3.20472,8797.94061,415.20090,0.02500,0.02500,1.25025
188.65002,3.21386,8803.17464,415.44791,0.02511,0.02511,1.25539
189.20002,3.22319,8807.67703,415.66037,0.02520,0.02520,1.26022
189.75002,3.23222,8811.92833,415.86099,0.02530,0.02530,1.26490
190.30000,3.24137,8817.97746,416.14648,0.02540,0.02540,1.26997
190.85000,3.25058,8822.16245,416.34399,0.02550,0.02550,1.27490
191.40002,3.25966,8825.29020,416.49158,0.02559,0.02559,1.27934
191.95002,3.26881,8828.93577,416.66364,0.02569,0.02569,1.28435
192.50002,3.27808,8835.15701,416.95724,0.02579,0.02579,1.28972
193.05000,3.28717,8839.91048,417.18158,0.02589,0.02589,1.29431
193.60000,3.29649,8844.27279,417.38742,0.02598,0.02598,1.29913
194.15002,3.30558,8849.62305,417.63992,0.02609,0.02609,1.30432
194.70002,3.31479,8854.22826,417.85727,0.02618,0.02618,1.30900
195.25002,3.32388,8856.67652,417.97281,0.02628,0.02628,1.31391
195.80000,3.33303,8860.57243,418.15668,0.02638,0.02638,1.31877
196.35000,3.34211,8863.90135,418.31375,0.02647,0.02647,1.32359
196.90002,3.35132,8872.53582,418.72125,0.02658,0.02658,1.32886
197.45002,3.36059,8877.80711,418.97003,0.02668,0.02668,1.33392
198.00002,3.36980,8880.32913,419.08905,0.02678,0.02678,1.33906
198.55000,3.37894,8886.32163,419.37186,0.02688,0.02688,1.34396
199.10000,3.38815,8891.34556,419.60895,0.02698,0.02698,1.34902
199.65002,3.39718,8894.20956,419.74411,0.02708,0.02708,1.35423
200.20002,3.40639,8898.06971,419.92627,0.02718,0.02718,1.35879
200.75002,3.41547,8899.67233,420.00189,0.02728,0.02728,1.36417
201.30000,3.42462,8906.26684,420.31311,0.02740,0.02740,1.36997
201.85000,3.43389,8911.52695,420.56137,0.02749,0.02749,1.37457
202.40002,3.44316,8915.25298,420.73721,0.02758,0.02758,1.37900
202.95002,3.45231,8921.56065,421.03488,0.02768,0.02768,1.38395
203.50002,3.46145,8924.79792,421.18765,0.02778,0.02778,1.38891
204.05000,3.47054,8928.59027,421.36664,0.02787,0.02787,1.39355
204.60000,3.47969,8933.68199,421.60693,0.02797,0.02797,1.39868
205.15002,3.48884,8934.75413,421.65753,0.02807,0.02807,1.40348
205.70002,3.49798,8939.92484,421.90155,0.02817,0.02817,1.40867
206.25002,3.50719,8945.56493,422.16772,0.02827,0.02827,1.41358
206.80000,3.51640,8951.03216,422.42572,0.02837,0.02837,1.41836
207.35000,3.52561,8956.65661,422.69116,0.02846,0.02846,1.42307
207.90002,3.53481,8958.68018,422.78665,0.02857,0.02857,1.42846
208.45002,3.54378,8961.67830,422.92816,0.02866,0.02866,1.43323
209.00002,3.55305,8967.36011,423.19629,0.02877,0.02877,1.43837
209.55000,3.56220,8970.28148,423.33417,0.02886,0.02886,1.44315
210.10000,3.57129,8975.24282,423.56830,0.02896,0.02896,1.44811
210.65002,3.58055,8979.99108,423.79239,0.02907,0.02907,1.45351
211.20002,3.58970,8983.17844,423.94281,0.02916,0.02916,1.45824
211.75002,3.59891,8989.20223,424.22708,0.02926,0.02926,1.46316
212.30000,3.60818,8992.76063,424.39502,0.02937,0.02937,1.46833
212.85000,3.61720,8996.90688,424.59070,0.02946,0.02946,1.47295
213.40002,3.62641,9001.02705,424.78513,0.02957,0.02957,1.47831
213.95002,3.63550,9003.88360,424.91995,0.02967,0.02967,1.48334
214.50002,3.64459,9007.48074,425.08969,0.02976,0.02976,1.48814
215.05000,3.65386,9011.82890,425.29489,0.02986,0.02986,1.49306
215.60000,3.66306,9017.37213,425.55652,0.02996,0.02996,1.49822
216.15002,3.67227,9023.44361,425.84305,0.03007,0.03007,1.50349
216.70002,3.68154,9026.70026,425.99673,0.03017,0.03017,1.50848
217.25002,3.69057,9031.16614,426.20749,0.03026,0.03026,1.51311
217.80000,3.69965,9033.47656,426.31653,0.03036,0.03036,1.51818
218.35000,3.70880,9035.51057,426.41251,0.03046,0.03046,1.52322
218.90002,3.71795,9039.58976,426.60501,0.03056,0.03056,1.52817
219.45002,3.72722,9043.88502,426.80774,0.03066,0.03066,1.53318
220.00002,3.73636,9049.44316,427.07004,0.03077,0.03077,1.53835
220.55000,3.74557,9054.32180,427.30026,0.03087,0.03087,1.54363
221.10000,3.75484,9058.21323,427.48392,0.03097,0.03097,1.54826
221.65002,3.76387,9061.77014,427.65179,0.03107,0.03107,1.55330
222.20002,3.77308,9064.59838,427.78525,0.03117,0.03117,1.55870
222.75002,3.78222,9069.64839,428.02359,0.03126,0.03126,1.56315
223.30000,3.79131,9072.18978,428.14352,0.03137,0.03137,1.56868
223.85000,3.80052,9075.91581,428.31937,0.03148,0.03148,1.57401
224.40002,3.80967,9080.16190,428.51974,0.03158,0.03158,1.57900
224.95002,3.81893,9085.60380,428.77655,0.03169,0.03169,1.58455
225.50002,3.82808,9089.44309,428.95773,0.03179,0.03179,1.58951
226.05002,3.83723,9094.76876,429.20908,0.03189,0.03189,1.59441
226.60000,3.84644,9096.60682,429.29584,0.03198,0.03198,1.59913
227.15002,3.85553,9100.36489,429.47318,0.03209,0.03209,1.60441
227.70002,3.86461,9101.85501,429.54352,0.03219,0.03219,1.60927
228.25002,3.87376,9105.56614,429.71863,0.03228,0.03228,1.61424
228.80002,3.88303,9111.43869,429.99579,0.03239,0.03239,1.61948
229.35000,3.89224,9114.50163,430.14032,0.03251,0.03251,1.62560
229.90002,3.90150,9120.14320,430.40659,0.03261,0.03261,1.63062
230.45002,3.91065,9124.05774,430.59131,0.03271,0.03271,1.63547
231.00002,3.91968,9123.97057,430.58719,0.03281,0.03281,1.64045
231.55002,3.92883,9130.61276,430.90067,0.03291,0.03291,1.64565
232.10000,3.93797,9130.77742,430.90845,0.03301,0.03301,1.65045
232.65002,3.94712,9136.75725,431.19064,0.03311,0.03311,1.65551
233.20002,3.95639,9141.92125,431.43436,0.03321,0.03321,1.66058
233.75002,3.96554,9144.07000,431.53577,0.03331,0.03331,1.66565
234.30002,3.97475,9148.77057,431.75760,0.03341,0.03341,1.67053
234.85000,3.98389,9153.61345,431.98615,0.03351,0.03351,1.67550
235.40002,3.99310,9156.37910,432.11667,0.03361,0.03361,1.68075
235.95002,4.00219,9160.04404,432.28961,0.03379,0.03379,1.68956
236.50002,4.01140,9162.61896,432.41113,0.03380,0.03380,1.68975
237.05002,4.02042,9165.41442,432.54306,0.03392,0.03392,1.69589
237.60000,4.02963,9170.50168,432.78314,0.03408,0.03408,1.70421
238.15002,4.03896,9173.99749,432.94812,0.03416,0.03416,1.70797
238.70002,4.04811,9178.28605,433.15051,0.03424,0.03424,1.71176
239.25002,4.05726,9181.84072,433.31827,0.03434,0.03434,1.71687
239.80002,4.06640,9185.19869,433.47675,0.03444,0.03444,1.72210
240.35000,4.07549,9187.95913,433.60703,0.03455,0.03455,1.72743
240.90002,4.08464,9187.19023,433.57074,0.03465,0.03465,1.73247
241.45002,4.09373,9192.50995,433.82178,0.03475,0.03475,1.73759
242.00002,4.10299,9198.97258,434.12677,0.03485,0.03485,1.74253
242.55002,4.11226,9202.03328,434.27121,0.03495,0.03495,1.74762
243.10000,4.12147,9205.88821,434.45312,0.03505,0.03505,1.75261
243.65002,4.13068,9209.16349,434.60770,0.03515,0.03515,1.75730
244.20002,4.13970,9211.69519,434.72717,0.03525,0.03525,1.76234
244.75002,4.14891,9217.03950,434.97940,0.03535,0.03535,1.76737
245.30002,4.15806,9218.40146,435.04367,0.03545,0.03545,1.77242
245.85000,4.16703,9219.82974,435.11108,0.03555,0.03555,1.77738
246.40002,4.17636,9225.79095,435.39240,0.03565,0.03565,1.78263
246.95002,4.18556,9228.02389,435.49777,0.03576,0.03576,1.78792
247.50002,4.19471,9232.18206,435.69403,0.03586,0.03586,1.79307
248.05002,4.20398,9237.53008,435.94641,0.03596,0.03596,1.79815
248.60000,4.21307,9240.07893,436.06671,0.03607,0.03607,1.80327
249.15002,4.22215,9242.37594,436.17511,0.03617,0.03617,1.80870
249.70002,4.23142,9246.87982,436.38766,0.03628,0.03628,1.81380
250.25002,4.24045,9246.98561,436.39264,0.03638,0.03638,1.81876
250.80002,4.24960,9250.08357,436.53885,0.03648,0.03648,1.82388
251.35000,4.25893,9255.35783,436.78775,0.03658,0.03658,1.82921
251.90002,4.26801,9259.40946,436.97897,0.03668,0.03668,1.83423
252.45002,4.27728,9263.47375,437.17078,0.03678,0.03678,1.83898
253.00002,4.28643,9267.12453,437.34305,0.03688,0.03688,1.84411
253.55002,4.29552,9267.79583,437.37476,0.03699,0.03699,1.84951
254.10000,4.30472,9271.18883,437.53488,0.03709,0.03709,1.85461
254.65002,4.31375,9272.78548,437.61023,0.03719,0.03719,1.85973
255.20002,4.32296,9275.65843,437.74579,0.03729,0.03729,1.86472
255.75002,4.33217,9281.62783,438.02753,0.03740,0.03740,1.86993
256.30002,4.34137,9284.81817,438.17807,0.03750,0.03750,1.87498
256.85000,4.35064,9289.04116,438.37738,0.03760,0.03760,1.88019
257.40003,4.35973,9290.05072,438.42502,0.03771,0.03771,1.88531
257.95002,4.36888,9294.40856,438.63068,0.03780,0.03780,1.89020
258.50000,4.37803,9296.82404,438.74466,0.03791,0.03791,1.89538
259.05002,4.38711,9299.18513,438.85611,0.03802,0.03802,1.90083
259.60000,4.39632,9301.45308,438.96313,0.03812,0.03812,1.90582
260.15003,4.40547,9305.20892,439.14038,0.03822,0.03822,1.91094
260.70002,4.41468,9309.53845,439.34470,0.03833,0.03833,1.91628
261.25000,4.42400,9314.63614,439.58527,0.03842,0.03842,1.92116
261.80002,4.43309,9318.04255,439.74603,0.03853,0.03853,1.92665
262.35000,4.44224,9318.63636,439.77405,0.03863,0.03863,1.93158
262.90003,4.45139,9322.78857,439.97000,0.03873,0.03873,1.93675
263.45000,4.46048,9324.41428,440.04672,0.03884,0.03884,1.94183
264.00000,4.46956,9324.12073,440.03287,0.03895,0.03895,1.94749
264.55003,4.47883,9331.70542,440.39084,0.03905,0.03905,1.95257
265.10000,4.48810,9333.39447,440.47055,0.03915,0.03915,1.95773
265.65003,4.49725,9337.69941,440.67371,0.03926,0.03926,1.96276
266.20000,4.50645,9342.09824,440.88129,0.03936,0.03936,1.96778
266.75000,4.51554,9342.77996,440.91345,0.03946,0.03946,1.97304
267.30003,4.52469,9347.96631,441.15823,0.03956,0.03956,1.97807
267.85000,4.53384,9348.37013,441.17728,0.03967,0.03967,1.98328
268.40003,4.54292,9350.16796,441.26212,0.03977,0.03977,1.98842
268.95000,4.55213,9357.56341,441.61115,0.03987,0.03987,1.99370
269.50000,4.56140,9359.55867,441.70529,0.03997,0.03997,1.99870
270.05003,4.57055,9363.82338,441.90656,0.04008,0.04008,2.00414
270.60000,4.57976,9366.01982,442.01022,0.04018,0.04018,2.00924
271.15003,4.58896,9368.90170,442.14624,0.04029,0.04029,2.01428
271.70000,4.59805,9371.72249,442.27936,0.04039,0.04039,2.01956
272.25000,4.60720,9372.73279,442.32703,0.04050,0.04050,2.02488
272.80003,4.61623,9372.90564,442.33517,0.04060,0.04060,2.03008
273.35000,4.62537,9379.21405,442.63290,0.04069,0.04069,2.03475
273.90003,4.63476,9381.96331,442.76263,0.04081,0.04081,2.04032
274.45000,4.64391,9387.19511,443.00955,0.04091,0.04091,2.04567
275.00000,4.65312,9391.16478,443.19690,0.04102,0.04102,2.05117
275.55003,4.66232,9392.80540,443.27432,0.04113,0.04113,2.05659
276.10000,4.67135,9396.05311,443.42758,0.04123,0.04123,2.06149
276.65003,4.68050,9397.23477,443.48334,0.04133,0.04133,2.06635
277.20000,4.68971,9399.75306,443.60220,0.04143,0.04143,2.07159
277.75000,4.69880,9402.75788,443.74399,0.04154,0.04154,2.07682
278.30003,4.70806,9404.05577,443.80527,0.04164,0.04164,2.08195
278.85000,4.71727,9409.00370,444.03876,0.04174,0.04174,2.08725
279.40003,4.72642,9412.09868,444.18481,0.04185,0.04185,2.09229
279.95000,4.73557,9414.54023,444.30005,0.04195,0.04195,2.09757
280.50000,4.74471,9418.00922,444.46375,0.04205,0.04205,2.10273
281.05003,4.75392,9418.57547,444.49048,0.04216,0.04216,2.10810
281.60000,4.76301,9420.25706,444.56982,0.04226,0.04226,2.11313
282.15003,4.77210,9422.84837,444.69214,0.04237,0.04237,2.11831
282.70000,4.78137,9427.31574,444.90295,0.04248,0.04248,2.12405
283.25000,4.79051,9429.92643,445.02615,0.04258,0.04258,2.12876
283.80003,4.79978,9434.55920,445.24481,0.04268,0.04268,2.13395
284.35000,4.80899,9435.84517,445.30548,0.04278,0.04278,2.13913
284.90003,4.81808,9439.34321,445.47058,0.04289,0.04289,2.14464
285.45000,4.82722,9441.45247,445.57010,0.04299,0.04299,2.14926
286.00000,4.83625,9442.62967,445.62567,0.04309,0.04309,2.15465
286.55003,4.84540,9444.39247,445.70886,0.04320,0.04320,2.15989
287.10000,4.85473,9449.48196,445.94904,0.04331,0.04331,2.16529
287.65003,4.86387,9453.25717,446.12720,0.04341,0.04341,2.17064
288.20000,4.87308,9455.56015,446.23590,0.04352,0.04352,2.17591
288.75000,4.88235,9459.13270,446.40451,0.04362,0.04362,2.18103
289.30003,4.89138,9460.01410,446.44611,0.04373,0.04373,2.18640
289.85000,4.90059,9461.83950,446.53223,0.04383,0.04383,2.19174
290.40003,4.90973,9464.81079,446.67245,0.04394,0.04394,2.19680
290.95000,4.91882,9464.46955,446.65637,0.04404,0.04404,2.20196
291.50000,4.92791,9469.05538,446.87277,0.04414,0.04414,2.20711
292.05003,4.93724,9474.89738,447.14847,0.04425,0.04425,2.21235
292.60000,4.94638,9474.25961,447.11838,0.04435,0.04435,2.21749
293.15003,4.95559,9478.48111,447.31760,0.04445,0.04445,2.22251
293.70000,4.96480,9481.13129,447.44269,0.04456,0.04456,2.22797
294.25000,4.97389,9482.93209,447.52765,0.04466,0.04466,2.23314
294.80003,4.98298,9484.19273,447.58716,0.04477,0.04477,2.23851
295.35000,4.99212,9484.71054,447.61160,0.04487,0.04487,2.24358
295.82000,5.00002,9489.24422,447.82556,0.04496,0.04496,2.24823
296.37003,5.06417,9639.69901,454.92596,0.04563,0.04563,2.28127
296.92000,5.12832,9640.31667,454.95511,0.04638,0.04638,2.31885
297.47000,5.19248,9649.46598,455.38690,0.04713,0.04713,2.35630
298.02003,5.25675,9663.06999,456.02890,0.04788,0.04788,2.39415
298.57000,5.32085,9677.17171,456.69440,0.04864,0.04864,2.43220
299.12003,5.38512,9690.89642,457.34210,0.04939,0.04939,2.46974
299.67000,5.44921,9704.73662,457.99527,0.05014,0.05014,2.50722
300.22000,5.51331,9722.36320,458.82712,0.05089,0.05089,2.54472
300.77003,5.57752,9736.17882,459.47913,0.05164,0.05164,2.58214
301.32000,5.64162,9749.20169,460.09372,0.05237,0.05237,2.61870
301.87003,5.70583,9764.11104,460.79733,0.05313,0.05313,2.65634
302.42000,5.77004,9779.07628,461.50357,0.05387,0.05387,2.69375
302.97000,5.83414,9792.11703,462.11902,0.05461,0.05461,2.73052
303.52003,5.89841,9806.32603,462.78958,0.05536,0.05536,2.76780
304.07000,5.96257,9821.46040,463.50381,0.05611,0.05611,2.80531
304.62003,6.02672,9832.72716,464.03552,0.05686,0.05686,2.84276
305.17000,6.09082,9844.44395,464.58847,0.05760,0.05760,2.88015
305.72000,6.15503,9858.14258,465.23495,0.05835,0.05835,2.91746
306.22600,6.21404,9869.71334,465.78101,0.05855,0.05905,2.95227
325.81403,6.26666,9880.93317,466.31052,0.05855,0.03757,1.87865
326.36400,6.33165,9911.20040,467.73892,0.05855,0.03525,1.76235
326.91400,6.39574,9919.92950,468.15085,0.05855,0.03429,1.71439
327.46403,6.46002,9927.07536,468.48810,0.05855,0.03426,1.71301
328.01400,6.52417,9933.48658,468.79065,0.05855,0.03515,1.75775
328.56403,6.58826,9943.48079,469.26233,0.05855,0.03684,1.84204
329.11400,6.65248,9952.24565,469.67596,0.05855,0.03882,1.94078
329.66400,6.71657,9960.67896,470.07394,0.05855,0.04113,2.05656
330.21403,6.78073,9971.26102,470.57333,0.05855,0.04287,2.14356
330.76400,6.84500,9982.03754,471.08191,0.05855,0.04411,2.20549
331.31403,6.90921,9987.39898,471.33496,0.05855,0.04442,2.22095
331.86400,6.97331,9997.67110,471.81973,0.05855,0.04437,2.21856
332.41400,7.03752,10007.75397,472.29556,0.05855,0.04375,2.18734
332.96403,7.10156,10015.13302,472.64380,0.05855,0.04249,2.12440
333.51400,7.16583,10025.22409,473.12003,0.05855,0.04109,2.05426
334.06403,7.23004,10033.79673,473.52460,0.05855,0.03948,1.97411
334.61400,7.29420,10039.50387,473.79395,0.05855,0.03850,1.92521
335.16400,7.35829,10047.95954,474.19299,0.05855,0.03792,1.89580
335.71403,7.42245,10055.69622,474.55811,0.05855,0.03756,1.87781
336.26400,7.48672,10063.96040,474.94812,0.05855,0.03754,1.87682
336.81403,7.55081,10071.89527,475.32257,0.05855,0.03792,1.89614
337.36400,7.61497,10078.76024,475.64655,0.05855,0.03849,1.92463
337.91400,7.67912,10084.52699,475.91870,0.05855,0.03939,1.96928
338.46403,7.74322,10091.16992,476.23221,0.05855,0.04031,2.01563
339.01400,7.80743,10099.72766,476.63608,0.05855,0.04138,2.06920
339.56403,7.87164,10105.92580,476.92859,0.05855,0.04205,2.10271
340.11400,7.93580,10110.52132,477.14545,0.05855,0.04249,2.12460
340.66400,7.99989,10118.01213,477.49896,0.05855,0.04285,2.14273
341.21403,8.06417,10125.86281,477.86948,0.05855,0.04252,2.12621
341.76400,8.12826,10130.42405,478.08472,0.05855,0.04215,2.10761
342.31403,8.19254,10134.29984,478.26764,0.05855,0.04117,2.05868
342.86400,8.25675,10141.14693,478.59076,0.05855,0.04036,2.01798
343.41400,8.32078,10146.03749,478.82156,0.05855,0.04005,2.00267
343.96403,8.38506,10152.54855,479.12885,0.05855,0.03940,1.97002
344.51400,8.44915,10157.34449,479.35516,0.05855,0.03891,1.94557
345.06403,8.51337,10161.62112,479.55701,0.05855,0.03855,1.92774
345.61400,8.57752,10166.87453,479.80493,0.05855,0.03835,1.91745
346.16400,8.64161,10171.81203,480.03793,0.05855,0.03850,1.92482
346.71403,8.70589,10174.63356,480.17111,0.05855,0.03901,1.95058
347.26400,8.77004,10181.87776,480.51297,0.05855,0.03974,1.98686
347.81403,8.83420,10185.94503,480.70493,0.05855,0.04028,2.01406
348.36400,8.89829,10188.88503,480.84366,0.05855,0.04081,2.04032
348.91400,8.96238,10194.60708,481.11371,0.05855,0.04115,2.05750
349.46403,9.02666,10197.34442,481.24289,0.05855,0.04151,2.07563
350.01400,9.09093,10200.81788,481.40683,0.05855,0.04153,2.07669
350.56403,9.15497,10203.74671,481.54504,0.05855,0.04151,2.07546
351.11400,9.21918,10208.64472,481.77618,0.05855,0.04140,2.06989
351.66400,9.28328,10212.67250,481.96628,0.05855,0.04125,2.06242
352.21403,9.34743,10216.34415,482.13956,0.05855,0.04092,2.04613
352.76400,9.41158,10219.50394,482.28867,0.05855,0.04058,2.02902
353.31403,9.47592,10223.89531,482.49591,0.05855,0.04033,2.01660
353.86400,9.53995,10224.11957,482.50650,0.05855,0.04001,2.00042
354.41403,9.60417,10230.33485,482.79980,0.05855,0.03984,1.99202
354.96403,9.66826,10230.16348,482.79172,0.05855,0.03975,1.98759
355.51400,9.73229,10233.88654,482.96744,0.05855,0.03963,1.98174
356.06403,9.79669,10239.33589,483.22461,0.05855,0.03981,1.99066
356.61400,9.86084,10241.54425,483.32883,0.05855,0.03989,1.99453
357.16403,9.92500,10240.14354,483.26273,0.05855,0.04007,2.00329
357.71403,9.98921,10244.62357,483.47415,0.05855,0.04019,2.00965
358.26400,10.05324,10248.26318,483.64590,0.05855,0.04048,2.02378
358.81403,10.11746,10248.37717,483.65128,0.05855,0.04063,2.03144
359.36400,10.18155,10251.23820,483.78632,0.05855,0.04072,2.03617
359.91403,10.24577,10254.37862,483.93451,0.05855,0.04082,2.04084
360.46403,10.30998,10255.60945,483.99258,0.05855,0.04079,2.03935
361.01400,10.37407,10256.74939,484.04639,0.05855,0.04070,2.03487
361.56403,10.43835,10259.57167,484.17960,0.05855,0.04061,2.03057
362.11400,10.50244,10260.12897,484.20587,0.05855,0.04047,2.02332
362.66403,10.56660,10262.58692,484.32187,0.05855,0.04027,2.01345
363.21403,10.63081,10264.56058,484.41501,0.05855,0.04033,2.01643
363.76400,10.69502,10267.32028,484.54526,0.05855,0.04013,2.00645
364.31403,10.75912,10266.38374,484.50107,0.05855,0.04007,2.00358
364.86400,10.82327,10268.87298,484.61853,0.05855,0.04008,2.00385
365.41403,10.88749,10269.96300,484.66998,0.05855,0.04013,2.00629
365.96403,10.95170,10270.07326,484.67517,0.05855,0.04018,2.00902
366.51400,11.01580,10273.22486,484.82391,0.05855,0.04023,2.01138
367.06403,11.08001,10273.85294,484.85355,0.05855,0.04028,2.01393
367.61400,11.14410,10273.21965,484.82367,0.05855,0.04038,2.01908
368.16403,11.20832,10274.77831,484.89722,0.05855,0.04041,2.02061
368.71403,11.27247,10276.47480,484.97729,0.05855,0.04048,2.02392
369.26400,11.33668,10277.18708,485.01089,0.05855,0.04053,2.02631
369.81403,11.40084,10277.39570,485.02075,0.05855,0.04053,2.02673
370.36400,11.46493,10279.19725,485.10577,0.05855,0.04054,2.02712
370.91403,11.52909,10279.13541,485.10284,0.05855,0.04051,2.02536
371.46403,11.59330,10278.80311,485.08716,0.05855,0.04049,2.02472
372.01400,11.65746,10280.29248,485.15747,0.05855,0.04046,2.02304
372.56403,11.72167,10281.58814,485.21860,0.05855,0.04039,2.01941
373.11400,11.78582,10279.24046,485.10782,0.05855,0.04035,2.01753
373.66403,11.85004,10282.38982,485.25644,0.05855,0.04030,2.01489
374.21403,11.91419,10282.81376,485.27646,0.05855,0.04029,2.01470
374.76400,11.97829,10280.70822,485.17709,0.05855,0.04026,2.01276
375.31403,12.04244,10281.47265,485.21317,0.05855,0.04031,2.01541
375.86400,12.10659,10281.76621,485.22702,0.05855,0.04024,2.01196
376.41403,12.17081,10281.73044,485.22531,0.05855,0.04027,2.01356
376.96403,12.23502,10281.53673,485.21619,0.05855,0.04028,2.01403
377.51400,12.29918,10282.20281,485.24762,0.05855,0.04034,2.01701
378.06403,12.36327,10280.98762,485.19028,0.05855,0.04025,2.01245
378.61400,12.42748,10281.93608,485.23502,0.05855,0.04039,2.01956
379.16403,12.49164,10281.77962,485.22763,0.05855,0.04053,2.02668
379.71403,12.55585,10279.58766,485.12421,0.05855,0.04062,2.03075
380.26400,12.62001,10279.80968,485.13467,0.05855,0.04047,2.02371
380.81403,12.68410,10280.26864,485.15634,0.05855,0.04050,2.02477
381.36400,12.74832,10280.70524,485.17694,0.05855,0.04041,2.02028
381.91403,12.81247,10280.30962,485.15826,0.05855,0.04041,2.02040
382.46403,12.87668,10279.95795,485.14166,0.05855,0.04041,2.02064
383.01400,12.94078,10277.09618,485.00662,0.05855,0.04039,2.01963
383.56403,13.00499,10276.91513,484.99808,0.05855,0.04039,2.01967
384.11400,13.06915,10276.06800,484.95810,0.05855,0.04037,2.01839
384.66403,13.13342,10275.66418,484.93903,0.05855,0.04055,2.02773
385.21403,13.19751,10274.64569,484.89096,0.05855,0.03962,1.98106
385.76400,13.26173,10275.20522,484.91739,0.05855,0.03912,1.95593
386.31403,13.32582,10273.11757,484.81885,0.05855,0.03947,1.97375
386.86400,13.38998,10270.59853,484.69998,0.05855,0.03974,1.98719
387.41403,13.45413,10271.11709,484.72446,0.05855,0.03998,1.99915
387.96403,13.51840,10270.06358,484.67471,0.05855,0.04042,2.02079
388.51400,13.58256,10267.99381,484.57706,0.05855,0.04096,2.04815
389.06403,13.64665,10268.97877,484.62354,0.05855,0.04117,2.05832
389.61400,13.71087,10267.86715,484.57108,0.05855,0.04111,2.05556
390.16403,13.77496,10263.27014,484.35413,0.05855,0.04110,2.05518
390.71403,13.83911,10261.68019,484.27908,0.05855,0.04109,2.05450
391.26400,13.90327,10262.72401,484.32834,0.05855,0.04042,2.02088
391.81403,13.96748,10259.89801,484.19498,0.05855,0.04039,2.01965
392.36400,14.03164,10259.38466,484.17075,0.05855,0.04036,2.01792
392.91403,14.09579,10257.80812,484.09634,0.05855,0.04047,2.02369
393.46403,14.15994,10254.41885,483.93640,0.05855,0.04050,2.02503
394.01400,14.22416,10253.45996,483.89114,0.05855,0.04051,2.02560
394.56403,14.28825,10250.59521,483.75595,0.05855,0.04054,2.02675
395.11400,14.35253,10249.63930,483.71085,0.05855,0.04052,2.02596
395.66403,14.41662,10246.54955,483.56503,0.05855,0.04047,2.02337
396.21403,14.48089,10245.39769,483.51068,0.05855,0.04041,2.02051
396.76400,14.54499,10242.75944,483.38617,0.05855,0.04022,2.01105
397.31403,14.60908,10239.19135,483.21777,0.05855,0.04027,2.01367
397.86400,14.67330,10236.50691,483.09109,0.05855,0.04027,2.01348
398.41403,14.73757,10235.60837,483.04868,0.05855,0.04033,2.01673
398.96403,14.80161,10229.82970,482.77597,0.05855,0.04024,2.01220
399.51400,14.86588,10228.58471,482.71722,0.05855,0.04024,2.01179
400.06403,14.93003,10225.98296,482.59442,0.05855,0.04013,2.00671
400.61400,14.99407,10222.40669,482.42566,0.05855,0.04031,2.01562
401.16403,15.05828,10218.27012,482.23044,0.05855,0.04057,2.02837
401.71403,15.12250,10215.16174,482.08374,0.05855,0.04067,2.03368
402.26400,15.18665,10210.08790,481.84430,0.05855,0.04055,2.02745
402.81403,15.25080,10204.84492,481.59686,0.05855,0.04064,2.03219
403.36400,15.31496,10203.62079,481.53909,0.05855,0.04061,2.03042
403.91403,15.37911,10196.20448,481.18909,0.05855,0.04056,2.02790
404.46403,15.44333,10190.58377,480.92383,0.05855,0.04048,2.02376
405.01400,15.50742,10184.59946,480.64142,0.05855,0.04038,2.01907
405.56403,15.57157,10178.73362,480.36459,0.05855,0.04030,2.01524
406.11400,15.63579,10171.43652,480.02023,0.05855,0.04022,2.01098
406.66403,15.70000,10163.53518,479.64734,0.05855,0.04017,2.00869
407.21403,15.76416,10156.33941,479.30774,0.05855,0.04018,2.00895
407.76400,15.82831,10146.49719,478.84326,0.05855,0.04018,2.00904
408.31403,15.89241,10136.49553,478.37125,0.05855,0.04019,2.00947
408.86400,15.95668,10126.49834,477.89944,0.05855,0.04028,2.01395
409.41403,16.02077,10112.97554,477.26126,0.05855,0.04039,2.01952
409.96403,16.08499,10101.41224,476.71558,0.05855,0.04063,2.03155
410.51400,16.14926,10088.47132,476.10486,0.05855,0.04065,2.03247
411.06403,16.21330,10072.33784,475.34348,0.05855,0.04072,2.03582
411.61400,16.27739,10057.09395,474.62405,0.05855,0.04065,2.03253
412.16403,16.34160,10038.53679,473.74829,0.05855,0.04049,2.02470
412.71403,16.40576,10018.01416,472.77975,0.05855,0.04035,2.01754
413.26400,16.46997,9997.93410,471.83212,0.05855,0.04020,2.00983
413.81403,16.53413,9977.52324,470.86887,0.05855,0.04011,2.00544
414.36400,16.59834,9951.76435,469.65323,0.05855,0.04003,2.00134
414.91403,16.66249,9928.34419,468.54797,0.05855,0.04004,2.00200
415.46403,16.72665,9901.38799,467.27582,0.05855,0.04014,2.00689
416.01400,16.79086,9871.76076,465.87762,0.05855,0.04026,2.01289
416.56403,16.85490,9839.69569,464.36438,0.05855,0.04054,2.02694
417.11400,16.91911,9808.30565,462.88300,0.05855,0.04088,2.04423
417.66403,16.98344,9773.02119,461.21783,0.05855,0.04064,2.03210
418.21403,17.04754,9734.48455,459.39917,0.05855,0.04067,2.03334
418.76400,17.11169,9693.58385,457.46893,0.05855,0.04052,2.02623
419.31403,17.17585,9649.42575,455.38498,0.05855,0.04040,2.02011
419.86400,17.23988,9600.66915,453.08401,0.05855,0.04027,2.01370
420.41403,17.30415,9547.32895,450.56674,0.05855,0.04017,2.00856
420.96403,17.36843,9490.61662,447.89032,0.05855,0.04014,2.00686
421.51400,17.43240,9424.33700,444.76239,0.05855,0.04010,2.00508
422.06403,17.49656,9348.85442,441.20013,0.05855,0.04011,2.00574
422.61400,17.56077,9264.08991,437.19986,0.05855,0.04009,2.00435
423.16403,17.62493,9162.08029,432.38571,0.05855,0.04010,2.00523
423.71403,17.68914,9041.43527,426.69211,0.05855,0.04010,2.00499
424.26400,17.75335,8899.30800,419.98471,0.05855,0.04038,2.01891
424.81403,17.81745,8724.66862,411.74295,0.05855,0.04043,2.02174
425.36400,17.88166,8514.63899,401.83102,0.05855,0.04058,2.02893
425.91403,17.94582,8256.24466,389.63666,0.05855,0.04064,2.03224
426.46403,18.01003,7924.50607,373.98093,0.05855,0.04068,2.03415
426.99203,18.07173,6163.51850,290.87469,0.05855,0.04058,2.02884