File: instron-3.csv
Time,Extension,Load,Tensile stress,Tensile strain,Strain 1,Displacement (Strain 1)
(sec),(mm),(N),(MPa),(mm/mm),(mm/mm),(mm)
0.00000,0.06607,307.06138,14.49114,0.00007,0.00007,0.00330
0.55000,0.07593,470.89383,22.22288,0.00011,0.00011,0.00573
1.10000,0.08532,592.26211,27.95060,0.00013,0.00013,0.00630
1.65000,0.09459,715.52508,33.76775,0.00016,0.00016,0.00780
2.20000,0.10367,841.45991,39.71099,0.00018,0.00018,0.00892
2.75000,0.11288,969.78461,45.76701,0.00021,0.00021,0.01058
3.30000,0.12197,1099.26611,51.87762,0.00024,0.00024,0.01184
3.85000,0.13100,1228.85192,57.99316,0.00027,0.00027,0.01330
4.40000,0.14021,1362.69815,64.30976,0.00030,0.00030,0.01489
4.95000,0.14947,1499.05132,70.74467,0.00032,0.00032,0.01621
5.50000,0.15868,1633.56550,77.09280,0.00036,0.00036,0.01785
6.05000,0.16789,1768.13286,83.44343,0.00038,0.00038,0.01896
6.60000,0.17704,1901.22332,89.72436,0.00041,0.00041,0.02072
7.15000,0.18618,2033.86284,95.98402,0.00043,0.00043,0.02168
7.70000,0.19527,2167.88817,102.30907,0.00047,0.00047,0.02342
8.25000,0.20442,2298.15971,108.45696,0.00048,0.00048,0.02409
8.80000,0.21357,2429.84388,114.67153,0.00051,0.00051,0.02541
9.35000,0.22284,2561.78379,120.89816,0.00054,0.00054,0.02692
9.90000,0.23204,2692.58805,127.07121,0.00058,0.00058,0.02896
10.45000,0.24119,2820.38432,133.10229,0.00060,0.00060,0.02995
11.00000,0.25040,2949.16928,139.18004,0.00063,0.00063,0.03171
11.55000,0.25949,3062.14709,144.51180,0.00065,0.00065,0.03265
12.10000,0.26857,3165.33111,149.38135,0.00067,0.00067,0.03368
12.65000,0.27784,3275.97000,154.60272,0.00070,0.00070,0.03484
13.20000,0.28687,3379.50774,159.48898,0.00071,0.00071,0.03562
13.75000,0.29608,3484.76768,164.45651,0.00073,0.00073,0.03668
14.30000,0.30534,3585.47121,169.20901,0.00077,0.00077,0.03827
14.85000,0.31449,3689.62623,174.12439,0.00078,0.00078,0.03906
15.40000,0.32376,3788.58298,178.79445,0.00080,0.00080,0.04022
15.95000,0.33285,3883.67325,183.28204,0.00082,0.00082,0.04120
16.50000,0.34200,3978.89987,187.77608,0.00084,0.00084,0.04222
17.05000,0.35114,4066.36633,191.90387,0.00086,0.00086,0.04287
17.60000,0.36023,4149.38964,195.82199,0.00088,0.00088,0.04400
18.15000,0.36938,4235.74597,199.89740,0.00090,0.00090,0.04510
18.70000,0.37865,4323.81444,204.05362,0.00092,0.00092,0.04596
19.25000,0.38785,4408.60614,208.05519,0.00093,0.00093,0.04668
19.80000,0.39712,4485.01743,211.66125,0.00095,0.00095,0.04750
20.35000,0.40621,4557.38790,215.07663,0.00096,0.00096,0.04797
20.90000,0.41536,4635.08479,218.74338,0.00099,0.00099,0.04927
21.45000,0.42451,4713.54648,222.44623,0.00100,0.00100,0.04996
22.00000,0.43353,4792.41684,226.16835,0.00101,0.00101,0.05049
22.55000,0.44274,4872.79445,229.96161,0.00103,0.00103,0.05143
23.10000,0.45195,4953.56731,233.77351,0.00105,0.00105,0.05235
23.65000,0.46116,5032.43431,237.49548,0.00106,0.00106,0.05310
24.20000,0.47042,5114.00737,241.34515,0.00108,0.00108,0.05386
24.75000,0.47951,5194.32984,245.13582,0.00109,0.00109,0.05450
25.30000,0.48866,5272.63433,248.83124,0.00111,0.00111,0.05566
25.85000,0.49781,5353.99467,252.67087,0.00114,0.00114,0.05682
26.40000,0.50690,5430.87572,256.29910,0.00115,0.00115,0.05744
26.95000,0.51604,5503.98529,259.74936,0.00117,0.00117,0.05855
27.50000,0.52531,5578.53058,263.26740,0.00118,0.00118,0.05902
28.05000,0.53452,5652.04807,266.73691,0.00120,0.00120,0.05990
28.60000,0.54373,5725.22059,270.19012,0.00121,0.00121,0.06044
29.15000,0.55287,5797.35860,273.59451,0.00123,0.00123,0.06132
29.70000,0.56196,5866.12076,276.83963,0.00124,0.00124,0.06221
30.25000,0.57111,5936.90202,280.17999,0.00126,0.00126,0.06275
30.80000,0.58026,6005.63623,283.42377,0.00127,0.00127,0.06345
31.35000,0.58940,6072.37630,286.57343,0.00128,0.00128,0.06418
31.90000,0.59861,6142.38009,289.87711,0.00130,0.00130,0.06502
32.45000,0.60782,6210.31597,293.08322,0.00132,0.00132,0.06589
33.00000,0.61703,6283.61702,296.54251,0.00133,0.00133,0.06653
33.55000,0.62618,6349.00779,299.62848,0.00135,0.00135,0.06756
34.10000,0.63538,6412.46811,302.62338,0.00136,0.00136,0.06820
34.65000,0.64447,6479.89362,305.80539,0.00137,0.00137,0.06869
35.20000,0.65356,6544.48047,308.85342,0.00139,0.00139,0.06952
35.75000,0.66271,6609.85708,311.93875,0.00141,0.00141,0.07048
36.30000,0.67191,6676.67389,315.09201,0.00141,0.00141,0.07067
36.85000,0.68118,6741.71075,318.16132,0.00143,0.00143,0.07168
37.40000,0.69039,6813.34138,321.54178,0.00145,0.00145,0.07246
37.95000,0.69960,6882.39262,324.80051,0.00147,0.00147,0.07333
38.50000,0.70868,6943.41883,327.68051,0.00148,0.00148,0.07409
39.05000,0.71777,7008.72764,330.76263,0.00150,0.00150,0.07491
39.60000,0.72692,7072.89204,333.79074,0.00151,0.00151,0.07531
40.15000,0.73601,7133.89441,336.66962,0.00152,0.00152,0.07614
40.70000,0.74528,7199.51987,339.76666,0.00154,0.00154,0.07686
41.25000,0.75448,7258.64246,342.55685,0.00155,0.00155,0.07766
41.80000,0.76369,7321.93366,345.54373,0.00157,0.00157,0.07829
42.35000,0.77290,7381.13374,348.33755,0.00159,0.00159,0.07935
42.90000,0.78199,7434.56706,350.85925,0.00160,0.00160,0.08014
43.45000,0.79113,7494.84301,353.70386,0.00162,0.00162,0.08096
44.00000,0.80034,7550.40795,356.32611,0.00163,0.00163,0.08147
44.55000,0.80937,7599.85521,358.65967,0.00164,0.00164,0.08218
45.10000,0.81858,7652.91005,361.16348,0.00166,0.00166,0.08291
45.65000,0.82785,7698.21554,363.30161,0.00167,0.00167,0.08355
46.20000,0.83693,7745.09534,365.51401,0.00168,0.00168,0.08417
46.75000,0.84626,7790.89928,367.67563,0.00169,0.00169,0.08446
47.30000,0.85541,7832.28949,369.62894,0.00171,0.00171,0.08546
47.85000,0.86450,7868.58574,371.34186,0.00172,0.00172,0.08594
48.40000,0.87364,7900.01303,372.82501,0.00174,0.00174,0.08683
48.95000,0.88273,7919.79879,373.75876,0.00174,0.00174,0.08714
49.50000,0.89188,7928.46605,374.16782,0.00175,0.00175,0.08767
50.05000,0.90121,7925.67357,374.03601,0.00176,0.00176,0.08782
50.60000,0.91035,7924.71692,373.99088,0.00177,0.00177,0.08838
51.15000,0.91956,7910.45278,373.31769,0.00176,0.00176,0.08799
51.70000,0.92877,7891.59909,372.42795,0.00176,0.00176,0.08777
52.25000,0.93780,7871.16364,371.46353,0.00175,0.00175,0.08760
52.80000,0.94701,7867.64771,371.29761,0.00175,0.00175,0.08746
53.35000,0.95609,7874.78536,371.63446,0.00174,0.00174,0.08722
53.90000,0.96524,7888.25452,372.27011,0.00176,0.00176,0.08789
54.45000,0.97451,7905.19118,373.06940,0.00177,0.00177,0.08854
55.00000,0.98366,7927.55485,374.12479,0.00177,0.00177,0.08873
55.55000,0.99286,7934.33636,374.44482,0.00178,0.00178,0.08887
56.10000,1.00207,7947.05376,375.04501,0.00178,0.00178,0.08912
56.65000,1.01122,7963.12615,375.80353,0.00179,0.00179,0.08940
57.20000,1.02037,7973.27757,376.28259,0.00179,0.00179,0.08955
57.75000,1.02940,7972.41777,376.24200,0.00179,0.00179,0.08961
58.30000,1.03860,7976.76742,376.44730,0.00179,0.00179,0.08972
58.85000,1.04775,7978.76716,376.54166,0.00180,0.00180,0.09010
59.40000,1.05696,7989.13613,377.03101,0.00180,0.00180,0.09004
59.95000,1.06623,8007.91085,377.91702,0.00181,0.00181,0.09026
60.50000,1.07543,8023.24861,378.64087,0.00180,0.00180,0.09014
61.05000,1.08452,8025.93082,378.76746,0.00181,0.00181,0.09055
61.60000,1.09367,8030.09868,378.96414,0.00182,0.00182,0.09079
62.15000,1.10276,8038.97679,379.38312,0.00182,0.00182,0.09086
62.70000,1.11191,8050.99234,379.95020,0.00183,0.00183,0.09145
63.25000,1.12111,8066.70636,380.69177,0.00183,0.00183,0.09163
63.80000,1.13038,8078.44028,381.24554,0.00184,0.00184,0.09200
64.35001,1.13959,8083.24069,381.47208,0.00185,0.00185,0.09225
64.90000,1.14880,8088.65577,381.72763,0.00185,0.00185,0.09228
65.45000,1.15782,8088.38531,381.71487,0.00185,0.00185,0.09255
66.00000,1.16697,8096.37159,382.09177,0.00185,0.00185,0.09239
66.55000,1.17618,8098.16793,382.17654,0.00186,0.00186,0.09306
67.10001,1.18527,8106.91118,382.58914,0.00186,0.00186,0.09278
67.65000,1.19441,8114.84978,382.96381,0.00186,0.00186,0.09314
68.20001,1.20374,8117.50516,383.08911,0.00186,0.00186,0.09322
68.75000,1.21283,8116.19982,383.02753,0.00187,0.00187,0.09349
69.30000,1.22204,8119.98472,383.20615,0.00187,0.00187,0.09333
69.85001,1.23124,8121.22673,383.26474,0.00186,0.00186,0.09323
70.40000,1.24033,8127.47031,383.55942,0.00187,0.00187,0.09367
70.95001,1.24948,8129.36872,383.64899,0.00188,0.00188,0.09381
71.50000,1.25863,8123.54460,383.37415,0.00188,0.00188,0.09402
72.05000,1.26766,8129.59149,383.65952,0.00188,0.00188,0.09410
72.60001,1.27704,8142.54060,384.27060,0.00189,0.00189,0.09442
73.15000,1.28619,8146.86418,384.47467,0.00189,0.00189,0.09467
73.70001,1.29546,8147.60551,384.50964,0.00190,0.00190,0.09497
74.25000,1.30461,8140.83889,384.19031,0.00190,0.00190,0.09484
74.80000,1.31369,8137.28422,384.02255,0.00190,0.00190,0.09486
75.35001,1.32284,8129.72561,383.66583,0.00190,0.00190,0.09508
75.90000,1.33193,8128.10436,383.58932,0.00191,0.00191,0.09554
76.45001,1.34108,8123.70926,383.38190,0.00191,0.00191,0.09539
77.00000,1.35041,8121.63353,383.28394,0.00192,0.00192,0.09576
77.55000,1.35955,8124.84622,383.43558,0.00194,0.00194,0.09706
78.10001,1.36870,8119.84912,383.19974,0.00197,0.00197,0.09844
78.65000,1.37797,8120.64037,383.23709,0.00202,0.00202,0.10079
79.20001,1.38700,8119.31640,383.17459,0.00210,0.00210,0.10524
79.75000,1.39620,8116.22813,383.02884,0.00220,0.00220,0.11019
80.30000,1.40529,8109.73346,382.72235,0.00233,0.00233,0.11660
80.85001,1.41438,8118.63318,383.14236,0.00245,0.00245,0.12271
81.40000,1.42365,8131.67468,383.75781,0.00258,0.00258,0.12897
81.95001,1.43286,8137.66122,384.04034,0.00273,0.00273,0.13671
82.50001,1.44206,8137.79235,384.04654,0.00292,0.00292,0.14576
83.05000,1.45127,8129.87313,383.67279,0.00310,0.00310,0.15506
83.60001,1.46036,8126.62244,383.51938,0.00329,0.00329,0.16470
84.15000,1.46951,8130.55634,383.70505,0.00346,0.00346,0.17292
84.70001,1.47865,8140.61463,384.17972,0.00363,0.00363,0.18128
85.25001,1.48774,8133.65653,383.85135,0.00379,0.00379,0.18965
85.80000,1.49701,8129.77403,383.66812,0.00398,0.00398,0.19911
86.35001,1.50616,8132.49648,383.79660,0.00413,0.00413,0.20648
86.90000,1.51536,8143.26033,384.30457,0.00430,0.00430,0.21493
87.45001,1.52463,8142.11443,384.25049,0.00444,0.00444,0.22200
88.00001,1.53372,8143.48012,384.31494,0.00460,0.00460,0.22984
88.55000,1.54287,8141.51689,384.22229,0.00477,0.00477,0.23866
89.10001,1.55208,8142.18149,384.25366,0.00495,0.00495,0.24748
89.65000,1.56110,8144.17601,384.34778,0.00512,0.00512,0.25614
90.20001,1.57031,8147.45948,384.50275,0.00529,0.00529,0.26439
90.75001,1.57952,8153.20313,384.77380,0.00544,0.00544,0.27225
91.30000,1.58867,8155.02033,384.85956,0.00563,0.00563,0.28174
91.85001,1.59787,8162.11775,385.19452,0.00577,0.00577,0.28862
92.40000,1.60714,8160.88617,385.13638,0.00596,0.00596,0.29783
92.95001,1.61623,8155.98890,384.90527,0.00614,0.00614,0.30712
93.50001,1.62532,8148.39527,384.54691,0.00631,0.00631,0.31567
94.05000,1.63441,8147.38125,384.49905,0.00649,0.00649,0.32464
94.60001,1.64361,8155.27961,384.87180,0.00666,0.00666,0.33291
95.15000,1.65282,8158.04750,385.00244,0.00682,0.00682,0.34105
95.70001,1.66209,8163.00660,385.23645,0.00699,0.00699,0.34927
96.25001,1.67124,8168.69214,385.50479,0.00716,0.00716,0.35782
96.80000,1.68044,8160.00104,385.09464,0.00733,0.00733,0.36636
97.35001,1.68947,8148.98983,384.57498,0.00750,0.00750,0.37499
97.90000,1.69862,8154.86386,384.85217,0.00769,0.00769,0.38436
98.45001,1.70777,8145.93881,384.43100,0.00787,0.00787,0.39346
99.00001,1.71697,8144.74225,384.37451,0.00804,0.00804,0.40223
99.55000,1.72612,8151.31068,384.68451,0.00822,0.00822,0.41088
100.10001,1.73539,8150.21768,384.63290,0.00839,0.00839,0.41937
100.65000,1.74454,8144.73331,384.37408,0.00856,0.00856,0.42821
101.20001,1.75375,8148.77152,384.56467,0.00875,0.00875,0.43755
101.75001,1.76289,8159.32825,385.06287,0.00891,0.00891,0.44570
102.30000,1.77204,8153.40951,384.78354,0.00909,0.00909,0.45430
102.85001,1.78113,8141.29561,384.21185,0.00929,0.00929,0.46461
103.40000,1.79022,8140.34864,384.16718,0.00946,0.00946,0.47292
103.95001,1.79942,8147.70311,384.51425,0.00964,0.00964,0.48216
104.50001,1.80875,8149.20217,384.58499,0.00982,0.00982,0.49084
105.05000,1.81790,8146.01481,384.43457,0.00998,0.00998,0.49918
105.60001,1.82717,8146.11465,384.43927,0.01014,0.01014,0.50718
106.15000,1.83620,8149.07029,384.57877,0.01034,0.01034,0.51692
106.70001,1.84534,8149.89954,384.61789,0.01053,0.01053,0.52648
107.25001,1.85449,8147.94526,384.52567,0.01072,0.01072,0.53584
107.80000,1.86358,8143.57698,384.31952,0.01089,0.01089,0.54470
108.35001,1.87279,8142.41171,384.26453,0.01107,0.01107,0.55348
108.90000,1.88205,8145.47539,384.40912,0.01126,0.01126,0.56284
109.45001,1.89120,8146.76955,384.47018,0.01143,0.01143,0.57137
110.00001,1.90047,8137.92124,384.05261,0.01162,0.01162,0.58079
110.55000,1.90950,8126.90631,383.53278,0.01179,0.01179,0.58940
111.10001,1.91864,8124.66070,383.42682,0.01197,0.01197,0.59874
111.65000,1.92785,8122.13197,383.30746,0.01218,0.01218,0.60876
112.20001,1.93694,8115.05914,382.97369,0.01237,0.01237,0.61872
112.75001,1.94609,8103.90711,382.44739,0.01254,0.01254,0.62718
113.30000,1.95536,8104.39438,382.47037,0.01272,0.01272,0.63611
113.85001,1.96444,8112.32477,382.84464,0.01290,0.01290,0.64523
114.40001,1.97377,8119.45051,383.18094,0.01308,0.01308,0.65389
114.95001,1.98292,8117.14828,383.07227,0.01325,0.01325,0.66246
115.50001,1.99207,8111.49776,382.80560,0.01343,0.01343,0.67142
116.05000,2.00115,8111.89637,382.82443,0.01360,0.01360,0.68022
116.60001,2.01024,8105.64011,382.52917,0.01379,0.01379,0.68970
117.15001,2.01939,8105.40393,382.51804,0.01397,0.01397,0.69852
117.70001,2.02866,8111.60579,382.81070,0.01415,0.01415,0.70726
118.25001,2.03781,8116.94637,383.06274,0.01433,0.01433,0.71638
118.80000,2.04713,8110.34366,382.75116,0.01451,0.01451,0.72556
119.35001,2.05622,8110.20210,382.74448,0.01469,0.01469,0.73429
119.90001,2.06537,8105.53432,382.52417,0.01487,0.01487,0.74368
120.45001,2.07452,8106.81507,382.58463,0.01505,0.01505,0.75245
121.00001,2.08360,8107.38951,382.61172,0.01523,0.01523,0.76135
121.55000,2.09275,8117.38819,383.08359,0.01540,0.01540,0.76983
122.10001,2.10196,8121.80266,383.29193,0.01557,0.01557,0.77854
122.65001,2.11117,8119.24189,383.17108,0.01577,0.01577,0.78849
123.20001,2.12049,8120.22984,383.21771,0.01595,0.01595,0.79769
123.75001,2.12952,8119.27617,383.17270,0.01611,0.01611,0.80548
124.30000,2.13861,8117.94251,383.10977,0.01628,0.01628,0.81416
124.85001,2.14788,8120.03985,383.20874,0.01647,0.01647,0.82339
125.40001,2.15697,8117.16244,383.07294,0.01665,0.01665,0.83255
125.95001,2.16611,8116.05453,383.02066,0.01681,0.01681,0.84061
126.50001,2.17532,8118.69800,383.14542,0.01699,0.01699,0.84971
127.05000,2.18447,8123.97525,383.39447,0.01715,0.01715,0.85770
127.60001,2.19374,8130.77018,383.71512,0.01735,0.01735,0.86746
128.15001,2.20294,8136.82601,384.00092,0.01753,0.01753,0.87674
128.70002,2.21209,8138.51953,384.08084,0.01769,0.01769,0.88438
129.25000,2.22112,8133.41066,383.83975,0.01787,0.01787,0.89358
129.80000,2.23033,8130.07876,383.68250,0.01806,0.01806,0.90288
130.35001,2.23936,8125.08017,383.44659,0.01822,0.01822,0.91119
130.90001,2.24862,8133.58054,383.84775,0.01840,0.01840,0.91980
131.45002,2.25789,8143.53451,384.31750,0.01860,0.01860,0.93008
132.00000,2.26710,8153.50190,384.78790,0.01875,0.01875,0.93740
132.55000,2.27625,8159.10324,385.05225,0.01893,0.01893,0.94646
133.10000,2.28545,8170.06156,385.56940,0.01907,0.01907,0.95360
133.65002,2.29442,8172.11419,385.66629,0.01930,0.01930,0.96486
134.20002,2.30369,8162.38821,385.20728,0.01946,0.01946,0.97283
134.75000,2.31278,8002.14559,377.64496,0.01975,0.01975,0.98767
135.30000,2.32192,8080.31559,381.33405,0.01988,0.01988,0.99416
135.85000,2.33119,8167.96944,385.47067,0.02000,0.02000,0.99994
136.40002,2.34040,8221.30293,387.98764,0.02010,0.02010,1.00505
136.95002,2.34961,8244.66571,389.09021,0.02023,0.02023,1.01137
137.50000,2.35876,8261.38407,389.87918,0.02030,0.02030,1.01508
138.05000,2.36784,8279.29676,390.72455,0.02043,0.02043,1.02163
138.60000,2.37699,8292.22798,391.33481,0.02050,0.02050,1.02508
139.15002,2.38608,8300.78498,391.73865,0.02059,0.02059,1.02967
139.70002,2.39523,8314.50745,392.38623,0.02070,0.02070,1.03523
140.25000,2.40449,8321.83361,392.73199,0.02082,0.02082,1.04078
140.80000,2.41364,8332.43653,393.23236,0.02089,0.02089,1.04474
141.35000,2.42291,8343.45296,393.75226,0.02099,0.02099,1.04953
141.90002,2.43212,8350.37902,394.07913,0.02110,0.02110,1.05489
142.45002,2.44115,8356.66582,394.37582,0.02122,0.02122,1.06088
143.00000,2.45041,8364.30490,394.73633,0.02131,0.02131,1.06557
143.55000,2.45944,8369.56948,394.98477,0.02142,0.02142,1.07117
144.10000,2.46853,8374.43024,395.21417,0.02153,0.02153,1.07637
144.65002,2.47786,8382.30774,395.58594,0.02161,0.02161,1.08070
145.20002,2.48694,8387.60957,395.83615,0.02170,0.02170,1.08503
145.75000,2.49621,8395.70090,396.21799,0.02181,0.02181,1.09050
146.30000,2.50548,8403.19693,396.57175,0.02192,0.02192,1.09616
146.85000,2.51451,8408.36689,396.81573,0.02203,0.02203,1.10128
147.40002,2.52371,8414.15375,397.08884,0.02212,0.02212,1.10619
147.95002,2.53280,8418.40208,397.28934,0.02224,0.02224,1.11185
148.50000,2.54189,8422.63326,397.48901,0.02231,0.02231,1.11548
149.05000,2.55116,8430.30289,397.85098,0.02241,0.02241,1.12065
149.60000,2.56037,8437.06951,398.17032,0.02253,0.02253,1.12663
150.15002,2.56957,8441.15317,398.36304,0.02263,0.02263,1.13146
150.70002,2.57878,8448.22749,398.69687,0.02271,0.02271,1.13574
151.25000,2.58787,8453.56137,398.94861,0.02283,0.02283,1.14130
151.80000,2.59696,8456.57960,399.09103,0.02292,0.02292,1.14591
152.35000,2.60610,8461.00897,399.30008,0.02302,0.02302,1.15105
152.90002,2.61525,8466.92622,399.57935,0.02313,0.02313,1.15658
153.45002,2.62452,8473.04538,399.86810,0.02322,0.02322,1.16080
154.00000,2.63367,8478.93506,400.14606,0.02330,0.02330,1.16490
154.55000,2.64287,8483.46055,400.35965,0.02344,0.02344,1.17176
155.10000,2.65202,8490.53487,400.69348,0.02352,0.02352,1.17575
155.65002,2.66117,8494.78468,400.89404,0.02360,0.02360,1.18009
156.20002,2.67038,8496.66148,400.98264,0.02372,0.02372,1.18600
156.75000,2.67953,8505.44423,401.39713,0.02378,0.02378,1.18912
157.30000,2.68861,8506.78012,401.46014,0.02391,0.02391,1.19575
157.85000,2.69770,8512.68023,401.73859,0.02399,0.02399,1.19932
158.40002,2.70697,8518.96480,402.03519,0.02409,0.02409,1.20433
158.95002,2.71624,8524.76731,402.30902,0.02419,0.02419,1.20961
159.50000,2.72538,8530.19133,402.56500,0.02426,0.02426,1.21297
160.05000,2.73453,8536.16670,402.84698,0.02440,0.02440,1.22017
160.60000,2.74374,8540.06037,403.03076,0.02446,0.02446,1.22286
161.15002,2.75283,8545.54474,403.28958,0.02459,0.02459,1.22938
161.70002,2.76192,8546.21306,403.32111,0.02467,0.02467,1.23354
162.25002,2.77106,8553.11379,403.64679,0.02477,0.02477,1.23833
162.80000,2.78027,8558.43052,403.89771,0.02486,0.02486,1.24286
163.35000,2.78948,8563.65785,404.14438,0.02499,0.02499,1.24970
163.90002,2.79869,8570.83797,404.48325,0.02506,0.02506,1.25299
164.45002,2.80795,8574.96038,404.67780,0.02518,0.02518,1.25896
165.00002,2.81698,8578.43459,404.84174,0.02524,0.02524,1.26214
165.55000,2.82613,8584.25424,405.11639,0.02537,0.02537,1.26859
166.10000,2.83528,8586.27558,405.21179,0.02546,0.02546,1.27281
166.65002,2.84437,8590.48665,405.41052,0.02556,0.02556,1.27804
167.20002,2.85369,8598.39320,405.78366,0.02565,0.02565,1.28236
167.75002,2.86284,8601.63793,405.93677,0.02575,0.02575,1.28746
168.30000,2.87199,8607.53283,406.21497,0.02584,0.02584,1.29208
168.85000,2.88126,8611.70292,406.41177,0.02594,0.02594,1.29677
169.40002,2.89034,8616.55101,406.64056,0.02605,0.02605,1.30252
169.95002,2.89949,8621.39463,406.86914,0.02612,0.02612,1.30589
170.50002,2.90870,8625.72938,407.07373,0.02623,0.02623,1.31133
171.05000,2.91767,8626.97214,407.13239,0.02633,0.02633,1.31640
171.60000,2.92688,8631.59597,407.35059,0.02643,0.02643,1.32160
172.15002,2.93620,8640.21331,407.75726,0.02653,0.02653,1.32658
172.70002,2.94535,8645.68055,408.01529,0.02663,0.02663,1.33145
173.25002,2.95462,8649.73292,408.20651,0.02673,0.02673,1.33636
173.80000,2.96371,8655.50563,408.47894,0.02682,0.02682,1.34114
174.35000,2.97279,8657.30122,408.56369,0.02692,0.02692,1.34601
174.90002,2.98194,8659.57737,408.67111,0.02702,0.02702,1.35077
175.45002,2.99103,8663.36450,408.84982,0.02711,0.02711,1.35555
176.00002,3.00024,8668.62908,409.09830,0.02721,0.02721,1.36029
176.55000,3.00944,8675.17069,409.40701,0.02729,0.02729,1.36472
177.10000,3.01871,8682.42383,409.74930,0.02739,0.02739,1.36941
177.65002,3.02798,8685.22078,409.88129,0.02751,0.02751,1.37526
178.20002,3.03695,8690.32219,410.12204,0.02762,0.02762,1.38092
178.75002,3.04615,8695.39082,410.36127,0.02771,0.02771,1.38527
179.30000,3.05536,8698.01119,410.48492,0.02780,0.02780,1.38986
179.85000,3.06433,8698.93506,410.52850,0.02791,0.02791,1.39530
180.40002,3.07360,8705.96990,410.86050,0.02801,0.02801,1.40059
180.95002,3.08281,8710.93199,411.09470,0.02810,0.02810,1.40509
181.50002,3.09195,8715.54166,411.31223,0.02819,0.02819,1.40964
182.05000,3.10134,8721.80462,411.60779,0.02829,0.02829,1.41463
182.60000,3.11037,8725.09181,411.76294,0.02839,0.02839,1.41931
183.15002,3.11946,8729.11289,411.95270,0.02848,0.02848,1.42421
183.70002,3.12866,8733.56238,412.16269,0.02857,0.02857,1.42853
184.25002,3.13769,8733.96024,412.18146,0.02868,0.02868,1.43381
184.80000,3.14690,8738.44251,412.39301,0.02877,0.02877,1.43872
185.35000,3.15617,8745.16442,412.71021,0.02888,0.02888,1.44378
185.90002,3.16532,8748.97689,412.89014,0.02896,0.02896,1.44824
186.45002,3.17452,8755.42462,413.19443,0.02907,0.02907,1.45332
187.00002,3.18373,8761.49684,413.48099,0.02916,0.02916,1.45805
187.55000,3.19282,8763.91158,413.59494,0.02925,0.02925,1.46271
188.10000,3.20197,8768.74849,413.82321,0.02940,0.02940,1.46980
188.65002,3.21117,8772.39406,413.99527,0.02950,0.02950,1.47507
189.20002,3.22020,8773.02885,414.02521,0.02959,0.02959,1.47954
189.75002,3.22947,8780.34607,414.37054,0.02969,0.02969,1.48457
190.30000,3.23868,8784.53031,414.56802,0.02979,0.02979,1.48927
190.85000,3.24788,8790.58018,414.85352,0.02990,0.02990,1.49480
191.40002,3.25703,8793.94189,415.01218,0.02998,0.02998,1.49897
191.95002,3.26624,8797.57851,415.18381,0.03011,0.03011,1.50534
192.50002,3.27527,8802.11070,415.39767,0.03023,0.03023,1.51146
193.05000,3.28442,8804.73256,415.52142,0.03033,0.03033,1.51647
193.60000,3.29356,8807.77463,415.66498,0.03041,0.03041,1.52040
194.15002,3.30271,8814.39596,415.97745,0.03053,0.03053,1.52640
194.70002,3.31198,8816.60506,416.08173,0.03062,0.03062,1.53122
195.25002,3.32125,8822.21386,416.34641,0.03072,0.03072,1.53615
195.80000,3.33039,8825.71191,416.51151,0.03082,0.03082,1.54117
196.35000,3.33954,8829.50872,416.69067,0.03091,0.03091,1.54557
196.90002,3.34863,8833.76151,416.89139,0.03101,0.03101,1.55059
197.45002,3.35778,8834.74052,416.93759,0.03112,0.03112,1.55602
198.00002,3.36687,8838.68709,417.12384,0.03122,0.03122,1.56079
198.55000,3.37613,8846.25837,417.48114,0.03132,0.03132,1.56591
199.10000,3.38540,8848.55390,417.58948,0.03141,0.03141,1.57059
199.65002,3.39449,8853.78197,417.83621,0.03152,0.03152,1.57605
200.20002,3.40376,8857.51843,418.01254,0.03161,0.03161,1.58051
200.75002,3.41284,8860.20809,418.13947,0.03172,0.03172,1.58593
201.30000,3.42199,8863.66665,418.30270,0.03181,0.03181,1.59052
201.85000,3.43120,8867.39716,418.47873,0.03190,0.03190,1.59505
202.40002,3.44023,8869.14060,418.56104,0.03201,0.03201,1.60043
202.95002,3.44944,8875.06828,418.84076,0.03211,0.03211,1.60530
203.50002,3.45864,8879.13927,419.03290,0.03221,0.03221,1.61053
204.05000,3.46779,8886.02808,419.35800,0.03231,0.03231,1.61559
204.60000,3.47712,8889.80627,419.53629,0.03241,0.03241,1.62035
205.15002,3.48621,8891.41485,419.61221,0.03251,0.03251,1.62566
205.70002,3.49529,8894.67299,419.76596,0.03263,0.03263,1.63159
206.25002,3.50450,8897.47888,419.89838,0.03269,0.03269,1.63472
206.80000,3.51353,8900.05082,420.01978,0.03282,0.03282,1.64077
207.35000,3.52274,8903.62263,420.18832,0.03294,0.03294,1.64681
207.90002,3.53200,8907.07895,420.35144,0.03306,0.03306,1.65282
208.45002,3.54115,8914.84544,420.71796,0.03311,0.03311,1.65569
209.00002,3.55042,8918.40830,420.88611,0.03327,0.03327,1.66331
209.55000,3.55957,8921.22835,421.01920,0.03335,0.03335,1.66745
210.10000,3.56866,8923.98134,421.14911,0.03344,0.03344,1.67188
210.65002,3.57786,8927.63138,421.32138,0.03355,0.03355,1.67754
211.20002,3.58695,8931.03033,421.48178,0.03365,0.03365,1.68235
211.75002,3.59610,8933.43091,421.59506,0.03375,0.03375,1.68756
212.30000,3.60531,8939.01065,421.85840,0.03383,0.03383,1.69155
212.85000,3.61451,8943.46386,422.06854,0.03396,0.03396,1.69785
213.40002,3.62372,8945.74821,422.17636,0.03405,0.03405,1.70244
213.95002,3.63287,8951.28548,422.43768,0.03415,0.03415,1.70768
214.50002,3.64202,8954.35512,422.58255,0.03425,0.03425,1.71251
215.05000,3.65116,8957.18560,422.71613,0.03434,0.03434,1.71695
215.60000,3.66025,8958.67869,422.78659,0.03445,0.03445,1.72259
216.15002,3.66940,8960.81999,422.88763,0.03455,0.03455,1.72752
216.70002,3.67861,8965.77090,423.12128,0.03464,0.03464,1.73215
217.25002,3.68782,8970.82686,423.35989,0.03474,0.03474,1.73707
217.80000,3.69708,8975.58853,423.58463,0.03484,0.03484,1.74217
218.35000,3.70629,8979.62973,423.77533,0.03494,0.03494,1.74692
218.90002,3.71538,8982.65094,423.91791,0.03505,0.03505,1.75258
219.45002,3.72453,8985.62670,424.05835,0.03514,0.03514,1.75721
220.00002,3.73361,8988.08017,424.17413,0.03524,0.03524,1.76177
220.55000,3.74270,8990.36527,424.28198,0.03535,0.03535,1.76761
221.10000,3.75191,8995.94948,424.54550,0.03546,0.03546,1.77290
221.65002,3.76118,9000.07710,424.74030,0.03555,0.03555,1.77731
222.20002,3.77038,9004.14512,424.93228,0.03566,0.03566,1.78301
222.75002,3.77959,9009.67270,425.19315,0.03576,0.03576,1.78801
223.30000,3.78874,9010.23000,425.21945,0.03586,0.03586,1.79296
223.85000,3.79783,9013.58873,425.37796,0.03596,0.03596,1.79803
224.40002,3.80704,9017.55840,425.56531,0.03607,0.03607,1.80326
224.95002,3.81618,9018.20362,425.59573,0.03616,0.03616,1.80780
225.50002,3.82521,9021.47666,425.75021,0.03627,0.03627,1.81347
226.05002,3.83454,9026.78296,426.00064,0.03637,0.03637,1.81859
226.60000,3.84369,9029.22451,426.11584,0.03646,0.03646,1.82322
227.15002,3.85289,9035.38987,426.40683,0.03656,0.03656,1.82815
227.70002,3.86210,9036.46648,426.45761,0.03667,0.03667,1.83367
228.25002,3.87119,9039.74995,426.61258,0.03682,0.03682,1.84099
228.80002,3.88028,9043.38434,426.78409,0.03691,0.03691,1.84536
229.35000,3.88949,9044.58612,426.84082,0.03698,0.03698,1.84903
229.90002,3.89851,9048.42913,427.02219,0.03709,0.03709,1.85458
230.45002,3.90784,9051.89887,427.18591,0.03723,0.03723,1.86155
231.00002,3.91699,9057.44284,427.44757,0.03732,0.03732,1.86584
231.55002,3.92626,9063.33327,427.72556,0.03740,0.03740,1.87020
232.10000,3.93546,9064.10664,427.76205,0.03755,0.03755,1.87752
232.65002,3.94449,9066.34256,427.86755,0.03763,0.03763,1.88137
233.20002,3.95364,9069.47628,428.01544,0.03774,0.03774,1.88676
233.75002,3.96285,9071.54679,428.11316,0.03785,0.03785,1.89230
234.30002,3.97188,9072.56082,428.16101,0.03794,0.03794,1.89679
234.85000,3.98120,9078.42219,428.43765,0.03805,0.03805,1.90242
235.40002,3.99035,9082.05435,428.60904,0.03815,0.03815,1.90737
235.95002,3.99950,9086.18793,428.80414,0.03825,0.03825,1.91225
236.50002,4.00883,9088.45216,428.91098,0.03835,0.03835,1.91739
237.05002,4.01791,9092.86514,429.11923,0.03845,0.03845,1.92261
237.60000,4.02706,9094.00731,429.17316,0.03856,0.03856,1.92787
238.15002,4.03621,9098.33983,429.37762,0.03866,0.03866,1.93293
238.70002,4.04524,9098.66020,429.39273,0.03875,0.03875,1.93754
239.25002,4.05445,9100.84918,429.49603,0.03886,0.03886,1.94286
239.80002,4.06365,9106.06682,429.74228,0.03895,0.03895,1.94766
240.35000,4.07292,9111.49904,429.99863,0.03906,0.03906,1.95318
240.90002,4.08213,9113.44141,430.09030,0.03916,0.03916,1.95809
241.45002,4.09122,9116.00888,430.21146,0.03927,0.03927,1.96339
242.00002,4.10030,9117.54072,430.28375,0.03935,0.03935,1.96770
242.55002,4.10945,9121.19672,430.45630,0.03946,0.03946,1.97313
243.10000,4.11854,9121.57670,430.47421,0.03956,0.03956,1.97794
243.65002,4.12781,9126.41659,430.70264,0.03966,0.03966,1.98291
244.20002,4.13695,9129.95040,430.86942,0.03976,0.03976,1.98819
244.75002,4.14622,9134.13465,431.06686,0.03987,0.03987,1.99336
245.30002,4.15543,9137.97989,431.24835,0.03996,0.03996,1.99808
245.85000,4.16452,9139.13921,431.30304,0.04007,0.04007,2.00344
246.40002,4.17373,9141.85792,431.43137,0.04017,0.04017,2.00849
246.95002,4.18287,9145.11830,431.58524,0.04027,0.04027,2.01353
247.50002,4.19190,9144.97152,431.57831,0.04038,0.04038,2.01878
248.05002,4.20111,9150.86642,431.85651,0.04048,0.04048,2.02389
248.60000,4.21038,9153.83995,431.99683,0.04058,0.04058,2.02885
249.15002,4.21952,9156.04606,432.10095,0.04068,0.04068,2.03419
249.70002,4.22873,9161.59078,432.36261,0.04078,0.04078,2.03924
250.25002,4.23800,9164.84818,432.51633,0.04088,0.04088,2.04418
250.80002,4.24703,9165.42709,432.54367,0.04098,0.04098,2.04921
251.35000,4.25617,9168.62488,432.69458,0.04109,0.04109,2.05462
251.90002,4.26526,9167.67493,432.64975,0.04119,0.04119,2.05946
252.45002,4.27441,9170.96958,432.80524,0.04129,0.04129,2.06462
253.00002,4.28362,9177.03807,433.09161,0.04140,0.04140,2.06983
253.55002,4.29295,9179.61895,433.21341,0.04150,0.04150,2.07495
254.10000,4.30203,9183.70262,433.40613,0.04160,0.04160,2.07992
254.65002,4.31130,9185.88489,433.50912,0.04171,0.04171,2.08535
255.20002,4.32033,9186.82441,433.55347,0.04180,0.04180,2.09024
255.75002,4.32948,9191.03175,433.75201,0.04192,0.04192,2.09592
256.30002,4.33862,9189.95291,433.70111,0.04200,0.04200,2.10018
256.85000,4.34777,9195.27411,433.95224,0.04214,0.04214,2.10679
257.40003,4.35698,9198.11726,434.08640,0.04222,0.04222,2.11123
257.95002,4.36625,9199.89944,434.17050,0.04231,0.04231,2.11569
258.50000,4.37534,9205.67960,434.44330,0.04245,0.04245,2.12242
259.05002,4.38460,9208.07570,434.55637,0.04253,0.04253,2.12638
259.60000,4.39375,9209.29536,434.61392,0.04264,0.04264,2.13204
260.15003,4.40290,9213.44459,434.80975,0.04275,0.04275,2.13749
260.70002,4.41199,9213.86927,434.82977,0.04284,0.04284,2.14220
261.25000,4.42101,9214.74919,434.87131,0.04293,0.04293,2.14674
261.80002,4.43028,9219.03700,435.07367,0.04307,0.04307,2.15343
262.35000,4.43955,9221.51282,435.19052,0.04315,0.04315,2.15752
262.90003,4.44870,9226.91151,435.44528,0.04328,0.04328,2.16414
263.45000,4.45802,9230.48258,435.61383,0.04336,0.04336,2.16812
264.00000,4.46699,9231.70745,435.67163,0.04349,0.04349,2.17464
264.55003,4.47620,9233.68484,435.76495,0.04356,0.04356,2.17814
265.10000,4.48535,9235.40071,435.84592,0.04368,0.04368,2.18394
265.65003,4.49438,9235.15707,435.83441,0.04381,0.04381,2.19037
266.20000,4.50364,9240.77928,436.09976,0.04390,0.04390,2.19521
266.75000,4.51285,9243.68799,436.23703,0.04401,0.04401,2.20034
267.30003,4.52200,9247.53919,436.41876,0.04411,0.04411,2.20567
267.85000,4.53133,9249.11499,436.49313,0.04422,0.04422,2.21096
268.40003,4.54029,9251.41498,436.60168,0.04432,0.04432,2.21609
268.95000,4.54950,9254.10911,436.72882,0.04442,0.04442,2.22123
269.50000,4.55865,9255.53516,436.79611,0.04452,0.04452,2.22624
270.05003,4.56774,9258.91250,436.95551,0.04464,0.04464,2.23181
270.60000,4.57695,9260.48011,437.02948,0.04474,0.04474,2.23712
271.15003,4.58621,9264.20167,437.20511,0.04485,0.04485,2.24260
271.70000,4.59530,9265.88327,437.28448,0.04496,0.04496,2.24803
272.25000,4.60463,9269.23230,437.44254,0.04506,0.04506,2.25293
272.80003,4.61378,9271.02417,437.52710,0.04516,0.04516,2.25798
273.35000,4.62286,9275.23822,437.72598,0.04527,0.04527,2.26333
273.90003,4.63201,9275.75454,437.75034,0.04538,0.04538,2.26900
274.45000,4.64110,9276.27683,437.77499,0.04548,0.04548,2.27421
275.00000,4.65025,9279.95890,437.94876,0.04558,0.04558,2.27906
275.55003,4.65951,9284.48960,438.16257,0.04569,0.04569,2.28464
276.10000,4.66872,9286.75160,438.26932,0.04579,0.04579,2.28938
276.65003,4.67793,9290.65198,438.45340,0.04591,0.04591,2.29528
277.20000,4.68708,9293.24105,438.57559,0.04602,0.04602,2.30093
277.75000,4.69623,9293.63444,438.59415,0.04611,0.04611,2.30544
278.30003,4.70531,9295.48740,438.68158,0.04623,0.04623,2.31138
278.85000,4.71446,9296.35391,438.72247,0.04632,0.04632,2.31619
279.40003,4.72361,9298.63676,438.83023,0.04644,0.04644,2.32198
279.95000,4.73282,9301.37187,438.95929,0.04654,0.04654,2.32705
280.50000,4.74202,9306.29075,439.19144,0.04664,0.04664,2.33224
281.05003,4.75129,9307.05667,439.22757,0.04675,0.04675,2.33751
281.60000,4.76038,9310.70969,439.39996,0.04685,0.04685,2.34239
282.15003,4.76953,9312.78318,439.49783,0.04697,0.04697,2.34866
282.70000,4.77868,9316.06740,439.65283,0.04706,0.04706,2.35300
283.25000,4.78776,9317.95612,439.74194,0.04716,0.04716,2.35799
283.80003,4.79691,9316.44365,439.67056,0.04729,0.04729,2.36429
284.35000,4.80612,9321.44076,439.90640,0.04739,0.04739,2.36970
284.90003,4.81533,9322.74908,439.96814,0.04749,0.04749,2.37473
285.45000,4.82453,9328.23569,440.22708,0.04761,0.04761,2.38041
286.00000,4.83380,9331.82314,440.39639,0.04772,0.04772,2.38595
286.55003,4.84289,9331.68530,440.38986,0.04779,0.04779,2.38934
287.10000,4.85198,9334.23191,440.51007,0.04791,0.04791,2.39555
287.65003,4.86118,9335.83975,440.58594,0.04805,0.04805,2.40245
288.20000,4.87027,9334.26693,440.51172,0.04814,0.04814,2.40686
288.75000,4.87942,9340.25645,440.79437,0.04825,0.04825,2.41257
289.30003,4.88875,9342.88204,440.91827,0.04838,0.04838,2.41893
289.85000,4.89784,9343.99664,440.97089,0.04847,0.04847,2.42372
290.40003,4.90704,9350.07334,441.25766,0.04856,0.04856,2.42812
290.95000,4.91631,9350.78412,441.29120,0.04868,0.04868,2.43408
291.50000,4.92528,9351.81007,441.33963,0.04879,0.04879,2.43944
292.05003,4.93449,9354.89610,441.48526,0.04889,0.04889,2.44457
292.60000,4.94363,9353.84631,441.43573,0.04900,0.04900,2.45020
293.15003,4.95272,9356.93681,441.58157,0.04911,0.04911,2.45526
293.70000,4.96199,9359.19583,441.68817,0.04921,0.04921,2.46056
294.25000,4.97126,9363.07907,441.87143,0.04932,0.04932,2.46590
294.80003,4.98040,9367.21712,442.06674,0.04943,0.04943,2.47141
295.35000,4.98961,9366.21279,442.01932,0.04952,0.04952,2.47598
295.90003,4.99864,9371.15029,442.25235,0.04964,0.04964,2.48225
296.37803,5.04611,9519.62322,449.25922,0.05010,0.05010,2.50517
296.92800,5.11087,9508.47641,448.73318,0.05089,0.05089,2.54465
297.47803,5.17496,9514.87869,449.03531,0.05166,0.05166,2.58293
298.02800,5.23905,9525.44734,449.53409,0.05241,0.05241,2.62060
298.57800,5.30327,9535.79098,450.02222,0.05317,0.05317,2.65861
299.12803,5.36742,9547.76928,450.58752,0.05394,0.05394,2.69677
299.67800,5.43158,9562.54750,451.28494,0.05469,0.05469,2.73427
300.22803,5.49585,9576.25210,451.93170,0.05544,0.05544,2.77223
300.77800,5.55988,9588.35557,452.50290,0.05621,0.05621,2.81061
301.32800,5.62404,9601.16014,453.10718,0.05696,0.05696,2.84797
301.87803,5.68825,9613.90212,453.70853,0.05772,0.05772,2.88615
302.42800,5.75241,9626.35428,454.29617,0.05848,0.05848,2.92410
319.35800,5.79934,9102.63211,429.58017,0.05855,0.10024,5.01203
319.90803,5.86409,9669.82767,456.34781,0.05855,0.14198,7.09913
320.45800,5.92861,9676.70828,456.67255,0.05855,0.13674,6.83707
321.00803,5.99282,9683.15825,456.97693,0.05855,0.07413,3.70665
321.55800,6.05697,9690.68855,457.33231,0.05855,0.16490,8.24479
322.10800,6.12119,9698.93932,457.72168,0.05855,0.17197,8.59855
322.65803,6.18528,9707.43895,458.12280,0.05855,0.13322,6.66086
323.20800,6.24944,9716.68810,458.55930,0.05855,0.07845,3.92255
323.75803,6.31365,9725.46190,458.97336,0.05855,0.09332,4.66577
324.30800,6.37780,9732.08100,459.28574,0.05855,0.09286,4.64281
324.85800,6.44190,9741.87702,459.74805,0.05855,0.12319,6.15962
325.40803,6.50611,9755.70753,460.40073,0.05855,0.11526,5.76277
325.95800,6.57033,9760.93709,460.64755,0.05855,0.11529,5.76470
326.50803,6.63442,9772.20088,461.17911,0.05855,0.11526,5.76319
327.05800,6.69864,9779.73714,461.53476,0.05855,0.11525,5.76258
327.60800,6.76273,9786.18041,461.83884,0.05855,0.11526,5.76278
328.15803,6.82682,9795.38262,462.27313,0.05855,0.11526,5.76288
328.70800,6.89110,9802.26621,462.59799,0.05855,0.11524,5.76220
329.25803,6.95531,9810.51251,462.98715,0.05855,0.11525,5.76229
329.80800,7.01947,9818.40715,463.35971,0.05855,0.11524,5.76209
330.35800,7.08356,9826.70337,463.75125,0.05855,0.11524,5.76208
330.90803,7.14777,9832.00520,464.00146,0.05855,0.11523,5.76165
331.45800,7.21187,9838.36800,464.30173,0.05855,0.11534,5.76681
332.00803,7.27614,9846.88103,464.70349,0.05855,0.11533,5.76654
332.55800,7.34036,9853.26990,465.00500,0.05855,0.11532,5.76589
333.10800,7.40445,9857.55622,465.20728,0.05855,0.11532,5.76596
333.65803,7.46860,9865.40765,465.57782,0.05855,0.11531,5.76547
334.20800,7.53276,9872.66675,465.92038,0.05855,0.11531,5.76530
334.75803,7.59691,9876.05080,466.08011,0.05855,0.11530,5.76507
335.30800,7.66113,9882.86212,466.40155,0.05855,0.11530,5.76493
335.85800,7.72522,9888.32712,466.65945,0.05855,0.11549,5.77449
336.40803,7.78937,9892.29009,466.84647,0.05855,0.11548,5.77394
336.95800,7.85353,9898.36529,467.13318,0.05855,0.11547,5.77349
337.50803,7.91768,9904.86667,467.44000,0.05855,0.11546,5.77284
338.05800,7.98202,9909.97478,467.68106,0.05855,0.11545,5.77274
338.60800,8.04599,9912.88424,467.81839,0.05855,0.11545,5.77261
339.15803,8.11014,9919.18296,468.11563,0.05855,0.11544,5.77202
339.70800,8.17436,9922.63258,468.27844,0.05855,0.11544,5.77209
340.25803,8.23851,9926.17235,468.44547,0.05855,0.11543,5.77151
340.80800,8.30279,9932.53812,468.74591,0.05855,0.11543,5.77143
341.35800,8.36700,9936.75590,468.94495,0.05855,0.11543,5.77159
341.90803,8.43110,9942.27454,469.20538,0.05855,0.11542,5.77118
342.45800,8.49531,9945.74204,469.36902,0.05855,0.11542,5.77105
343.00803,8.55952,9949.40996,469.54214,0.05855,0.11542,5.77109
343.55800,8.62368,9948.91599,469.51883,0.05855,0.11541,5.77074
344.10800,8.68771,9954.78109,469.79562,0.05855,0.11541,5.77050
344.65803,8.75199,9960.03821,470.04370,0.05855,0.11541,5.77071
345.20800,8.81608,9960.66630,470.07336,0.05855,0.11541,5.77037
345.75803,8.88029,9965.33111,470.29349,0.05855,0.11541,5.77034
346.30800,8.94451,9969.92439,470.51025,0.05855,0.11540,5.77004
346.85800,9.00854,9969.91917,470.51001,0.05855,0.11540,5.76982
347.40803,9.07270,9975.08168,470.75366,0.05855,0.11539,5.76965
347.95800,9.13697,9978.68031,470.92349,0.05855,0.11540,5.76984
348.50803,9.20118,9981.46087,471.05472,0.05855,0.11541,5.77025
349.05800,9.26528,9982.79154,471.11749,0.05855,0.11540,5.76987
349.60800,9.32937,9984.82779,471.21359,0.05855,0.11539,5.76957
350.15803,9.39359,9988.51433,471.38757,0.05855,0.11539,5.76950
350.70800,9.45768,9989.98880,471.45715,0.05855,0.11539,5.76930
351.25803,9.52195,9993.32741,471.61472,0.05855,0.11538,5.76913
351.80800,9.58623,9994.78549,471.68353,0.05855,0.11536,5.76788
352.35800,9.65020,9996.00440,471.74106,0.05855,0.11539,5.76948
352.90803,9.71448,10000.92179,471.97311,0.05855,0.11502,5.75093
353.45800,9.77857,10001.39266,471.99536,0.05855,0.11504,5.75185
354.00803,9.84273,10003.61666,472.10031,0.05855,0.11493,5.74648
354.55800,9.90694,10005.02408,472.16672,0.05855,0.11503,5.75156
355.10800,9.97115,10007.14824,472.26697,0.05855,0.11504,5.75180
355.65803,10.03531,10008.26284,472.31958,0.05855,0.11504,5.75194
356.20800,10.09946,10010.61648,472.43066,0.05855,0.11504,5.75184
356.75803,10.16362,10013.66302,472.57443,0.05855,0.11505,5.75262
357.30800,10.22771,10013.38363,472.56125,0.05855,0.11506,5.75281
357.85803,10.29192,10015.80730,472.67563,0.05855,0.11506,5.75314
358.40803,10.35608,10015.91980,472.68094,0.05855,0.11505,5.75262
358.95800,10.42029,10016.14556,472.69159,0.05855,0.11505,5.75238
359.50803,10.48445,10018.58637,472.80676,0.05855,0.11505,5.75246
360.05800,10.54854,10020.29255,472.88730,0.05855,0.11505,5.75251
360.60803,10.61275,10020.23965,472.88480,0.05855,0.11505,5.75271
361.15803,10.67691,10022.00693,472.96820,0.05855,0.11506,5.75281
361.70800,10.74106,10022.90547,473.01059,0.05855,0.11500,5.74986
362.25803,10.80534,10021.98905,472.96735,0.05855,0.11505,5.75240
362.80800,10.86943,10022.94719,473.01257,0.05855,0.11508,5.75421
363.35803,10.93358,10025.31350,473.12424,0.05855,0.11509,5.75436
363.90803,10.99780,10025.57129,473.13641,0.05855,0.11510,5.75500
364.45800,11.06195,10027.54644,473.22961,0.05855,0.11510,5.75518
365.00803,11.12605,10027.30057,473.21802,0.05855,0.11511,5.75530
365.55800,11.19032,10026.90047,473.19913,0.05855,0.11511,5.75546
366.10803,11.25448,10027.65223,473.23462,0.05855,0.11509,5.75430
366.65803,11.31863,10026.54806,473.18250,0.05855,0.11524,5.76204
367.20800,11.38278,10028.85476,473.29138,0.05855,0.11523,5.76150
367.75803,11.44688,10028.52842,473.27597,0.05855,0.11523,5.76167
368.30800,11.51097,10029.47390,473.32059,0.05855,0.11523,5.76138
368.85803,11.57525,10030.74944,473.38077,0.05855,0.11523,5.76132
369.40803,11.63940,10027.40115,473.22278,0.05855,0.11522,5.76085
369.95800,11.70349,10029.58119,473.32565,0.05855,0.11523,5.76127
370.50803,11.76783,10030.76285,473.38141,0.05855,0.11523,5.76126
371.05800,11.83192,10029.10361,473.30310,0.05855,0.11522,5.76112
371.60803,11.89602,10028.48372,473.27386,0.05855,0.11522,5.76088
372.15803,11.96023,10030.77850,473.38214,0.05855,0.11522,5.76081
372.70800,12.02444,10027.82881,473.24295,0.05855,0.11522,5.76101
373.25803,12.08854,10028.93001,473.29492,0.05855,0.11522,5.76084
373.80800,12.15275,10029.87698,473.33960,0.05855,0.11521,5.76074
374.35803,12.21703,10028.22146,473.26147,0.05855,0.11522,5.76091
374.90803,12.28112,10027.04576,473.20599,0.05855,0.11521,5.76067
375.45800,12.34527,10028.04562,473.25317,0.05855,0.11521,5.76073
376.00803,12.40949,10028.90915,473.29395,0.05855,0.11522,5.76078
376.55800,12.47352,10026.39979,473.17551,0.05855,0.11521,5.76057
377.10803,12.53774,10025.27028,473.12219,0.05855,0.11522,5.76077
377.65803,12.60195,10026.51379,473.18088,0.05855,0.11521,5.76053
378.20800,12.66605,10024.13034,473.06842,0.05855,0.11521,5.76029
378.75803,12.73014,10024.41570,473.08188,0.05855,0.11521,5.76064
379.30800,12.79441,10023.37635,473.03284,0.05855,0.11521,5.76035
379.85803,12.85851,10022.87716,473.00928,0.05855,0.11520,5.76015
380.40803,12.92284,10023.71535,473.04883,0.05855,0.11521,5.76047
380.95800,12.98688,10020.66806,472.90500,0.05855,0.11521,5.76043
381.50803,13.05121,10021.51147,472.94482,0.05855,0.11521,5.76041
382.05800,13.11524,10020.43784,472.89413,0.05855,0.11521,5.76041
382.60803,13.17940,10019.18092,472.83484,0.05855,0.11521,5.76037
383.15803,13.24361,10018.47610,472.80157,0.05855,0.11520,5.76011
383.70800,13.30777,10017.50231,472.75562,0.05855,0.11520,5.76010
384.25803,13.37186,10015.32674,472.65295,0.05855,0.11521,5.76030
384.80800,13.43631,10015.71938,472.67148,0.05855,0.11520,5.76016
385.35803,13.50035,10012.27945,472.50912,0.05855,0.11521,5.76037
385.90803,13.56444,10012.53426,472.52115,0.05855,0.11520,5.75996
386.45800,13.62871,10010.68503,472.43390,0.05855,0.11520,5.76018
387.00803,13.69275,10009.08762,472.35849,0.05855,0.11520,5.76005
387.55800,13.75685,10007.16984,472.26801,0.05855,0.11521,5.76027
388.10803,13.82112,10005.29304,472.17941,0.05855,0.11520,5.75998
388.65803,13.88527,10003.74332,472.10629,0.05855,0.11520,5.76014
389.20800,13.94937,10002.78741,472.06116,0.05855,0.11520,5.76001
389.75803,14.01352,10001.88515,472.01859,0.05855,0.11520,5.76014
390.30800,14.07779,10001.06186,471.97974,0.05855,0.11521,5.76027
390.85803,14.14195,9999.54715,471.90826,0.05855,0.11520,5.75988
391.40803,14.20610,9997.29112,471.80179,0.05855,0.11520,5.76006
391.95800,14.27026,9994.18870,471.65536,0.05855,0.11520,5.76005
392.50803,14.33435,9993.20894,471.60913,0.05855,0.11520,5.75992
393.05800,14.39862,9992.25974,471.56433,0.05855,0.11520,5.75993
393.60803,14.46290,9989.13273,471.41678,0.05855,0.11520,5.76003
394.15803,14.52693,9987.40420,471.33521,0.05855,0.11520,5.76001
394.70800,14.59109,9986.24638,471.28055,0.05855,0.11519,5.75974
395.25803,14.65530,9983.17525,471.13562,0.05855,0.11519,5.75961
395.80800,14.71934,9979.36279,470.95569,0.05855,0.11520,5.75987
396.35803,14.78367,9978.53503,470.91663,0.05855,0.11519,5.75975
396.90803,14.84782,9974.03935,470.70447,0.05855,0.11519,5.75963
397.45800,14.91198,9973.86724,470.69635,0.05855,0.11519,5.75967
398.00803,14.97607,9971.66336,470.59235,0.05855,0.11519,5.75951
398.55800,15.04035,9969.07726,470.47028,0.05855,0.11519,5.75958
399.10803,15.10432,9964.97422,470.27664,0.05855,0.11519,5.75932
399.65803,15.16853,9963.74935,470.21884,0.05855,0.11519,5.75959
400.20800,15.23281,9961.19082,470.09811,0.05855,0.11519,5.75949
400.75803,15.29690,9957.48639,469.92328,0.05855,0.11519,5.75959
401.30800,15.36112,9955.80405,469.84390,0.05855,0.11519,5.75966
401.85803,15.42521,9954.37652,469.77652,0.05855,0.11519,5.75961
402.40803,15.48943,9949.00316,469.52292,0.05855,0.11519,5.75931
402.95800,15.55364,9947.21204,469.43842,0.05855,0.11519,5.75939
403.50803,15.61773,9942.39450,469.21106,0.05855,0.11519,5.75939
404.05800,15.68195,9937.79004,468.99374,0.05855,0.11519,5.75947
404.60803,15.74610,9936.17848,468.91769,0.05855,0.11519,5.75940
405.15803,15.81026,9933.08648,468.77179,0.05855,0.11519,5.75959
405.70800,15.87441,9929.48934,468.60202,0.05855,0.11519,5.75955
406.25803,15.93862,9924.67925,468.37503,0.05855,0.11519,5.75942
406.80800,16.00278,9919.27087,468.11978,0.05855,0.11518,5.75920
407.35803,16.06705,9914.22832,467.88181,0.05855,0.11519,5.75956
407.90803,16.13114,9911.45968,467.75116,0.05855,0.11519,5.75929
408.45800,16.19524,9906.27185,467.50632,0.05855,0.11519,5.75928
409.00803,16.25945,9901.62641,467.28708,0.05855,0.11519,5.75927
409.55800,16.32349,9895.69202,467.00702,0.05855,0.11518,5.75911
410.10803,16.38770,9889.73826,466.72604,0.05855,0.11518,5.75917
410.65803,16.45198,9884.74637,466.49048,0.05855,0.11518,5.75913
411.20800,16.51619,9877.87470,466.16617,0.05855,0.11518,5.75921
411.75803,16.58022,9872.02600,465.89017,0.05855,0.11518,5.75922
412.30800,16.64444,9866.53864,465.63120,0.05855,0.11518,5.75900
412.85803,16.70865,9859.16927,465.28342,0.05855,0.11518,5.75924
413.40803,16.77275,9851.86920,464.93890,0.05855,0.11518,5.75903
413.95800,16.83696,9844.60637,464.59613,0.05855,0.11518,5.75912
414.50803,16.90111,9834.58683,464.12329,0.05855,0.11442,5.72123
415.05800,16.96527,9826.77117,463.75446,0.05855,0.11591,5.79551
415.60803,17.02948,9817.56747,463.32010,0.05855,0.11588,5.79413
416.15803,17.09370,9808.06202,462.87149,0.05855,0.11592,5.79586
416.70800,17.15773,9797.14096,462.35611,0.05855,0.11591,5.79546
417.25803,17.22189,9785.72369,461.81729,0.05855,0.11589,5.79455
417.80800,17.28610,9772.43185,461.19000,0.05855,0.08471,4.23554
418.35803,17.35013,9761.23363,460.66153,0.05855,0.08468,4.23405
418.90803,17.41447,9748.49835,460.06052,0.05855,0.08469,4.23444
419.45800,17.47868,9732.56305,459.30847,0.05855,0.08469,4.23438
420.00803,17.54271,9718.69677,458.65408,0.05855,0.08468,4.23419
420.55800,17.60681,9703.66895,457.94489,0.05855,0.08468,4.23415
421.10803,17.67114,9685.74956,457.09921,0.05855,0.08468,4.23395
421.65803,17.73524,9666.75803,456.20294,0.05855,0.08468,4.23391
422.20800,17.79945,9650.79144,455.44943,0.05855,0.08468,4.23414
422.75803,17.86361,9629.28534,454.43451,0.05855,0.08468,4.23385
423.30800,17.92782,9605.59845,453.31665,0.05855,0.08467,4.23362
423.85803,17.99191,9582.79967,452.24069,0.05855,0.08467,4.23366
424.40803,18.05613,9558.63222,451.10016,0.05855,0.08467,4.23355
424.95800,18.12022,9529.58539,449.72937,0.05855,0.08467,4.23336
425.50803,18.18437,9503.13956,448.48132,0.05855,0.08467,4.23335
426.05800,18.24865,9471.79645,447.00214,0.05855,0.08467,4.23334
426.60803,18.31280,9438.86861,445.44818,0.05855,0.08467,4.23346
427.15803,18.37702,9404.09228,443.80698,0.05855,0.08466,4.23304
427.70800,18.44105,9364.90670,441.95770,0.05855,0.08466,4.23306
428.25803,18.50527,9322.21264,439.94284,0.05855,0.08467,4.23330
428.80800,18.56948,9277.11353,437.81448,0.05855,0.08466,4.23324
429.35803,18.63363,9223.36876,435.27811,0.05855,0.08466,4.23277
429.90803,18.69779,9165.91808,432.56683,0.05855,0.08466,4.23290
430.45800,18.76188,9098.58644,429.38925,0.05855,0.08466,4.23311
431.00803,18.82610,9021.28369,425.74109,0.05855,0.08465,4.23265
431.55800,18.89031,8929.10361,421.39084,0.05855,0.08466,4.23289
432.10803,18.95447,8819.79913,416.23245,0.05855,0.08465,4.23257
432.65803,19.01862,8691.34665,410.17041,0.05855,0.08465,4.23268
433.20800,19.08277,8537.82371,402.92520,0.05855,0.08465,4.23263
433.75803,19.14693,8350.45949,394.08292,0.05855,0.08465,4.23269
434.30800,19.21108,8128.71233,383.61801,0.05855,0.08465,4.23248
434.85803,19.27529,7847.95657,370.36832,0.05855,0.08465,4.23265
435.22803,19.31876,5696.51127,268.83524,0.05855,0.08465,4.23243